Workbook

Sheet Calculator
A1: Tips | B1: Cook | C1: Helper | D1: Psistaria | E1: Waiter | F1: Waiter/prep | G1: Cashier
A2: Weight | B2: Fixed Share | C2: Fixed Share | D2: Fixed Share | E2: 1 | F2: 1 | G2: 1 | I2: For staff | J2: =SUM(B12:Z14) -> 52.8
A3: 55 | B3: 0.3 | C3: 0.15 | D3: 0.04 | E3: =1-D3-C3-B3 -> 0.51 | F3: =E3 -> 0.51 | G3: =E3 -> 0.51 | I3: For restaurant | J3: =A3-J2 -> 2.2
B5: Anastasia | C5: Aftap | D5: Eva | E5: Giannis | F5: Xristiana | G5: Xristis | H5: Amanta | I5: Tania | J5: Marina | K5: Anelia | L5: Natalia | M5: Pantelo | N5: Maria | O5: Dio
B6: Cook | C6: Cook | D6: Cook | E6: Waiter/prep | F6: Waiter/prep | G6: Waiter | H6: Helper | I6: Helper | J6: Helper | K6: Helper | L6: Helper | M6: Cashier | N6: Cashier | O6: Cook | P6: Cashier | Q6: Cashier | R6: Cashier
A7: Hours | B7: 4 | C7: 4 | D7: 4 | E7: 7 | F7: 6 | G7: 0 | H7: 2 | I7: 0 | J7: 0 | K7: 4 | L7: 0 | M7: 7 | N7: 0 | O7: 4 | P7: 0 | Q7: 0 | R7: 0
A8: Proportion | B8: =B7/SUM($B7:$Z7) -> 0.095238095 | C8: =C7/SUM($B7:$Z7) -> 0.095238095 | D8: =D7/SUM($B7:$Z7) -> 0.095238095 | E8: =E7/SUM($B7:$Z7) -> 0.16666667 | F8: =F7/SUM($B7:$Z7) -> 0.14285714 | G8: =G7/SUM($B7:$Z7) -> 0 | H8: =H7/SUM($B7:$Z7) -> 0.047619048 | I8: =I7/SUM($B7:$Z7) -> 0 | ... R8: =R7/SUM($B7:$Z7) -> 0
A9: Profession total | B9: =SUMIF($B$6:$Z$6,B6,$B$7:$Z$7) -> 16 | C9: =SUMIF($B$6:$Z$6,C6,$B$7:$Z$7) -> 16 | D9: =SUMIF($B$6:$Z$6,D6,$B$7:$Z$7) -> 16 | E9: =SUMIF($B$6:$Z$6,E6,$B$7:$Z$7) -> 13 | F9: =SUMIF($B$6:$Z$6,F6,$B$7:$Z$7) -> 13 | G9: =SUMIF($B$6:$Z$6,G6,$B$7:$Z$7) -> 0 | H9: =SUMIF($B$6:$Z$6,H6,$B$7:$Z$7) -> 6 | I9: =SUMIF($B$6:$Z$6,I6,$B$7:$Z$7) -> 6 | ... R9: =SUMIF($B$6:$Z$6,R6,$B$7:$Z$7) -> 7
A10: Share of profession | B10: =IFERROR(B7/B9,0) -> 0.25 | C10: =IFERROR(C7/C9,0) -> 0.25 | D10: =IFERROR(D7/D9,0) -> 0.25 | E10: =IFERROR(E7/E9,0) -> 0.53846154 | F10: =IFERROR(F7/F9,0) -> 0.46153846 | G10: =IFERROR(G7/G9,0) -> 0 | H10: =IFERROR(H7/H9,0) -> 0.33333333 | I10: =IFERROR(I7/I9,0) -> 0 | ... R10: =IFERROR(R7/R9,0) -> 0
B11: =HLOOKUP(B6,$B$1:$G$3,3,0) -> 0.3 | C11: =HLOOKUP(C6,$B$1:$G$3,3,0) -> 0.3 | D11: =HLOOKUP(D6,$B$1:$G$3,3,0) -> 0.3 | E11: =HLOOKUP(E6,$B$1:$G$3,3,0) -> 0.51 | F11: =HLOOKUP(F6,$B$1:$G$3,3,0) -> 0.51 | G11: =HLOOKUP(G6,$B$1:$G$3,3,0) -> 0.51 | H11: =HLOOKUP(H6,$B$1:$G$3,3,0) -> 0.15 | I11: =HLOOKUP(I6,$B$1:$G$3,3,0) -> 0.15 | ... R11: =HLOOKUP(R6,$B$1:$G$3,3,0) -> 0.51
A12: Cook share | B12: =IF(B6=$B$1, $A$3*B10*B11,0) -> 4.125 | C12: =IF(C6=$B$1, $A$3*C10*C11,0) -> 4.125 | D12: =IF(D6=$B$1, $A$3*D10*D11,0) -> 4.125 | E12: =IF(E6=$B$1, $A$3*E10*E11,0) -> 0 | F12: =IF(F6=$B$1, $A$3*F10*F11,0) -> 0 | G12: =IF(G6=$B$1, $A$3*G10*G11,0) -> 0 | H12: =IF(H6=$B$1, $A$3*H10*H11,0) -> 0 | I12: =IF(I6=$B$1, $A$3*I10*I11,0) -> 0 | ... R12: =IF(R6=$B$1, $A$3*R10*R11,0) -> 0
A13: Helper Share | B13: =IF(B6=$C$1, $A$3*B10*B11,0) -> 0 | C13: =IF(C6=$C$1, $A$3*C10*C11,0) -> 0 | D13: =IF(D6=$C$1, $A$3*D10*D11,0) -> 0 | E13: =IF(E6=$C$1, $A$3*E10*E11,0) -> 0 | F13: =IF(F6=$C$1, $A$3*F10*F11,0) -> 0 | G13: =IF(G6=$C$1, $A$3*G10*G11,0) -> 0 | H13: =IF(H6=$C$1, $A$3*H10*H11,0) -> 2.75 | I13: =IF(I6=$C$1, $A$3*I10*I11,0) -> 0 | ... R13: =IF(R6=$C$1, $A$3*R10*R11,0) -> 0
A14: Amount | B14: =B17/SUM($B$17:$Z$17) -> 0 | C14: =C17/SUM($B$17:$Z$17) -> 0 | D14: =D17/SUM($B$17:$Z$17) -> 0 | E14: =(E17/SUM($B$17:$Z$17))*$E$3*$A$3 -> 9.8175 | F14: =(F17/SUM($B$17:$Z$17))*$E$3*$A$3 -> 8.415 | G14: =(G17/SUM($B$17:$Z$17))*$E$3*$A$3 -> 0 | H14: =(H17/SUM($B$17:$Z$17))*$E$3*$A$3 -> 0 | I14: =(I17/SUM($B$17:$Z$17))*$E$3*$A$3 -> 0 | J14: =(J17/SUM($B$17:$Z$17))*$E$3*$A$3 -> 0 | K14: =(K17/SUM($B$17:$Z$17))*$E$3*$A$3 -> 0 | L14: =(L17/SUM($B$17:$Z$17))*$E$3*$A$3 -> 0 | ... R14: =(R17/SUM($B$17:$Z$17))*$E$3*$A$3 -> 0
A17: Points | B17: =IFNA(HLOOKUP(B6,$E$1:$G$2,2,0)*B18*B7,0) -> 0 | C17: =IFNA(HLOOKUP(C6,$E$1:$G$2,2,0)*C18*C7,0) -> 0 | D17: =IFNA(HLOOKUP(D6,$E$1:$G$2,2,0)*D18*D7,0) -> 0 | E17: =IFNA(HLOOKUP(E6,$E$1:$G$2,2,0)*E18*E7,0) -> 7 | F17: =IFNA(HLOOKUP(F6,$E$1:$G$2,2,0)*F18*F7,0) -> 6 | G17: =IFNA(HLOOKUP(G6,$E$1:$G$2,2,0)*G18*G7,0) -> 0 | H17: =IFNA(HLOOKUP(H6,$E$1:$G$2,2,0)*H18*H7,0) -> 0 | I17: =IFNA(HLOOKUP(I6,$E$1:$G$2,2,0)*I18*I7,0) -> 0 | ... R17: =IFNA(HLOOKUP(R6,$E$1:$G$2,2,0)*R18*R7,0) -> 0
A18: Remaining Share? | B18: =IF(SUM(B12:B13),0,1) -> 0 | C18: =IF(SUM(C12:C13),0,1) -> 0 | D18: =IF(SUM(D12:D13),0,1) -> 0 | E18: =IF(SUM(E12:E13),0,1) -> 1 | F18: =IF(SUM(F12:F13),0,1) -> 1 | G18: =IF(SUM(G12:G13),0,1) -> 1 | H18: =IF(SUM(H12:H13),0,1) -> 0 | I18: =IF(SUM(I12:I13),0,1) -> 1 | ... R18: =IF(SUM(R12:R13),0,1) -> 1

Sheet Weights
A1: Dates | B1: Cook | C1: Help | D1: Waiter | E1: Waiter/pre | F1: Cash
A2: 45597 | B2: 0.6 | C2: 0.6 | D2: 0.9 | E2: 1 | F2: 1
A3: =A2+1 -> 45598 | B3: 0.6 | C3: 0.6 | D3: 0.9 | E3: 1 | F3: 1
A4: =A3+1 -> 45599 | B4: 0.6 | C4: 0.6 | D4: 0.9 | E4: 1 | F4: 1
A5: =A4+1 -> 45600 | B5: 0.6 | C5: 0.6 | D5: 0.9 | E5: 1 | F5: 1
A6: =A5+1 -> 45601 | B6: 0.6 | C6: 0.6 | D6: 0.9 | E6: 1 | F6: 1
A7: =A6+1 -> 45602 | B7: 0.6 | C7: 0.6 | D7: 0.9 | E7: 1 | F7: 1
A8: =A7+1 -> 45603 | B8: 0.6 | C8: 0.6 | D8: 0.9 | E8: 1 | F8: 1
A9: =A8+1 -> 45604 | B9: 0.6 | C9: 0.6 | D9: 0.9 | E9: 1 | F9: 1
A10: =A9+1 -> 45605 | B10: 0.6 | C10: 0.6 | D10: 0.9 | E10: 1 | F10: 1
A11: =A10+1 -> 45606 | B11: 0.6 | C11: 0.6 | D11: 0.9 | E11: 1 | F11: 1
A12: =A11+1 -> 45607 | B12: 0.6 | C12: 0.6 | D12: 0.9 | E12: 1 | F12: 1
A13: =A12+1 -> 45608 | B13: 0.6 | C13: 0.6 | D13: 0.9 | E13: 1 | F13: 1
A14: =A13+1 -> 45609 | B14: 0.6 | C14: 0.6 | D14: 0.9 | E14: 1 | F14: 1
... A467: =A466+1 -> 46062 | B467: 0.6 | C467: 0.6 | D467: 0.9 | E467: 1 | F467: 1
A468: =A467+1 -> 46063 | B468: =IFERROR( Hours!D468/SUM(Hours!$D468:$Z468),) | C468: =IFERROR( Hours!F468/SUM(Hours!$D468:$Z468),) | D468: =IFERROR( Hours!G468/SUM(Hours!$D468:$Z468),) | E468: =IFERROR( Hours!C468/SUM(Hours!$D468:$Z468),) | F468: =IFERROR( Hours!H468/SUM(Hours!$D468:$Z468),)
A469: =A468+1 -> 46064 | B469: =IFERROR( Hours!D469/SUM(Hours!$D469:$Z469),) | C469: =IFERROR( Hours!F469/SUM(Hours!$D469:$Z469),) | D469: =IFERROR( Hours!G469/SUM(Hours!$D469:$Z469),) | E469: =IFERROR( Hours!C469/SUM(Hours!$D469:$Z469),) | F469: =IFERROR( Hours!H469/SUM(Hours!$D469:$Z469),)
A470: =A469+1 -> 46065 | B470: =IFERROR( Hours!D470/SUM(Hours!$D470:$Z470),) | C470: =IFERROR( Hours!F470/SUM(Hours!$D470:$Z470),) | D470: =IFERROR( Hours!G470/SUM(Hours!$D470:$Z470),) | E470: =IFERROR( Hours!C470/SUM(Hours!$D470:$Z470),) | F470: =IFERROR( Hours!H470/SUM(Hours!$D470:$Z470),)
A471: =A470+1 -> 46066 | B471: =IFERROR( Hours!D471/SUM(Hours!$D471:$Z471),) | C471: =IFERROR( Hours!F471/SUM(Hours!$D471:$Z471),) | D471: =IFERROR( Hours!G471/SUM(Hours!$D471:$Z471),) | E471: =IFERROR( Hours!C471/SUM(Hours!$D471:$Z471),) | F471: =IFERROR( Hours!H471/SUM(Hours!$D471:$Z471),)
A472: =A471+1 -> 46067 | B472: =IFERROR( Hours!D472/SUM(Hours!$D472:$Z472),) | C472: =IFERROR( Hours!F472/SUM(Hours!$D472:$Z472),) | D472: =IFERROR( Hours!G472/SUM(Hours!$D472:$Z472),) | E472: =IFERROR( Hours!C472/SUM(Hours!$D472:$Z472),) | F472: =IFERROR( Hours!H472/SUM(Hours!$D472:$Z472),)
A473: =A472+1 -> 46068 | B473: =IFERROR( Hours!D473/SUM(Hours!$D473:$Z473),) | C473: =IFERROR( Hours!F473/SUM(Hours!$D473:$Z473),) | D473: =IFERROR( Hours!G473/SUM(Hours!$D473:$Z473),) | E473: =IFERROR( Hours!C473/SUM(Hours!$D473:$Z473),) | F473: =IFERROR( Hours!H473/SUM(Hours!$D473:$Z473),)
A474: =A473+1 -> 46069 | B474: =IFERROR( Hours!D474/SUM(Hours!$D474:$Z474),) | C474: =IFERROR( Hours!F474/SUM(Hours!$D474:$Z474),) | D474: =IFERROR( Hours!G474/SUM(Hours!$D474:$Z474),) | E474: =IFERROR( Hours!C474/SUM(Hours!$D474:$Z474),) | F474: =IFERROR( Hours!H474/SUM(Hours!$D474:$Z474),)
A475: =A474+1 -> 46070 | B475: =IFERROR( Hours!D475/SUM(Hours!$D475:$Z475),) | C475: =IFERROR( Hours!F475/SUM(Hours!$D475:$Z475),) | D475: =IFERROR( Hours!G475/SUM(Hours!$D475:$Z475),) | E475: =IFERROR( Hours!C475/SUM(Hours!$D475:$Z475),) | F475: =IFERROR( Hours!H475/SUM(Hours!$D475:$Z475),)
A476: =A475+1 -> 46071 | B476: =IFERROR( Hours!D476/SUM(Hours!$D476:$Z476),) | C476: =IFERROR( Hours!F476/SUM(Hours!$D476:$Z476),) | D476: =IFERROR( Hours!G476/SUM(Hours!$D476:$Z476),) | E476: =IFERROR( Hours!C476/SUM(Hours!$D476:$Z476),) | F476: =IFERROR( Hours!H476/SUM(Hours!$D476:$Z476),)
A477: =A476+1 -> 46072 | B477: =IFERROR( Hours!D477/SUM(Hours!$D477:$Z477),) | C477: =IFERROR( Hours!F477/SUM(Hours!$D477:$Z477),) | D477: =IFERROR( Hours!G477/SUM(Hours!$D477:$Z477),) | E477: =IFERROR( Hours!C477/SUM(Hours!$D477:$Z477),) | F477: =IFERROR( Hours!H477/SUM(Hours!$D477:$Z477),)
A478: =A477+1 -> 46073 | B478: =IFERROR( Hours!D478/SUM(Hours!$D478:$Z478),) | C478: =IFERROR( Hours!F478/SUM(Hours!$D478:$Z478),) | D478: =IFERROR( Hours!G478/SUM(Hours!$D478:$Z478),) | E478: =IFERROR( Hours!C478/SUM(Hours!$D478:$Z478),) | F478: =IFERROR( Hours!H478/SUM(Hours!$D478:$Z478),)
A479: =A478+1 -> 46074 | B479: =IFERROR( Hours!D479/SUM(Hours!$D479:$Z479),) | C479: =IFERROR( Hours!F479/SUM(Hours!$D479:$Z479),) | D479: =IFERROR( Hours!G479/SUM(Hours!$D479:$Z479),) | E479: =IFERROR( Hours!C479/SUM(Hours!$D479:$Z479),) | F479: =IFERROR( Hours!H479/SUM(Hours!$D479:$Z479),)
... A659: =A658+1 -> 46254 | B659: =IFERROR( Hours!D659/SUM(Hours!$D659:$Z659),) | C659: =IFERROR( Hours!F659/SUM(Hours!$D659:$Z659),) | D659: =IFERROR( Hours!G659/SUM(Hours!$D659:$Z659),) | E659: =IFERROR( Hours!C659/SUM(Hours!$D659:$Z659),) | F659: =IFERROR( Hours!H659/SUM(Hours!$D659:$Z659),)
A660: =A659+1 -> 46255
A661: =A660+1 -> 46256
A662: =A661+1 -> 46257
A663: =A662+1 -> 46258
A664: =A663+1 -> 46259
A665: =A664+1 -> 46260
A666: =A665+1 -> 46261
A667: =A666+1 -> 46262
A668: =A667+1 -> 46263
A669: =A668+1 -> 46264
A670: =A669+1 -> 46265
A671: =A670+1 -> 46266
...

Sheet 2024
B1: Tips | C1: Day | D1: Αναστασία | E1: Αυτάπ | F1: Εύα | G1: Γιάννης | H1: Χριστιάνα | I1: Κρίστης | J1: Γκάμπριελ | K1: Τάνια | L1: Μαρίνα | M1: Ανέλια | N1: Ναταλία | O1: Παντελίτσα | P1: Μαρία | Q1: Διομήδης | R1: Αμάντα | S1: Ανθούλα | U1: Ψησταριά
D2: Cook | E2: Cook | F2: Cook | G2: Waiter/pre | H2: Waiter/pre | I2: Waiter/pre | J2: Help | K2: Help | L2: Help | M2: Waiter | N2: Help | O2: Cash | P2: Cash | Q2: Waiter | R2: Waiter/pre | S2: Help | T2: Cook | U2: Cook | V2: Help | W2: Waiter | X2: Waiter/pre | Y2: Cash
A3: =IF( WEEKDAY(C3)=1,1,) | B3: 55 | C3: 45597 | D3: 4 | E3: 4 | F3: 4 | G3: 7 | H3: 6 | J3: 2 | M3: 4 | O3: 7 | Q3: 4 | U3: 0.6 | V3: 0.6 | W3: 0.9 | X3: 1 | Y3: 1
A4: =IF( WEEKDAY(C4)=1,1,) | B4: 65 | C4: 45598 | D4: 4 | E4: 4 | F4: 4 | G4: 7 | H4: 6 | I4: 4 | M4: 3.5 | O4: 3.5 | Q4: 4 | U4: Psistaria
A5: =IF( WEEKDAY(C5)=1,1,) -> 1 | B5: 82 | C5: 45599 | D5: 4 | E5: 4 | F5: 4 | G5: 7 | H5: 6 | I5: 4 | J5: 2 | M5: 4 | O5: 7 | Q5: 4 | U5: 0.02
A6: =IF( WEEKDAY(C6)=1,1,) | D6: Points
A7: =IF( WEEKDAY(C7)=1,1,) | D7: =IFERROR(SUM(D3:D5)*HLOOKUP(D2, $U2:$Y3,2,0),) -> 7.2 | E7: =IFERROR(SUM(E3:E5)*HLOOKUP(E2, $U$2:$Y$3,2,0),) -> 7.2 | F7: =IFERROR(SUM(F3:F5)*HLOOKUP(F2, $U$2:$Y$3,2,0),) -> 7.2 | G7: =IFERROR(SUM(G3:G5)*HLOOKUP(G2, $U$2:$Y$3,2,0),) -> 21 | H7: =IFERROR(SUM(H3:H5)*HLOOKUP(H2, $U$2:$Y$3,2,0),) -> 18 | I7: =IFERROR(SUM(I3:I5)*HLOOKUP(I2, $U$2:$Y$3,2,0),) -> 8 | J7: =IFERROR(SUM(J3:J5)*HLOOKUP(J2, $U$2:$Y$3,2,0),) -> 2.4 | K7: =IFERROR(SUM(K3:K5)*HLOOKUP(K2, $U$2:$Y$3,2,0),) -> 0 | L7: =IFERROR(SUM(L3:L5)*HLOOKUP(L2, $U$2:$Y$3,2,0),) -> 0 | ... T7: =IFERROR(SUM(T3:T5)*HLOOKUP(T2, $U$2:$Y$3,2,0),) -> 0
A8: =IF( WEEKDAY(C8)=1,1,) | D8: Percent of points
A9: =IF( WEEKDAY(C9)=1,1,) | D9: =D7/SUM($D$7:$T$7) -> 0.065663475 | E9: =E7/SUM($D$7:$T$7) -> 0.065663475 | F9: =F7/SUM($D$7:$T$7) -> 0.065663475 | G9: =G7/SUM($D$7:$T$7) -> 0.19151847 | H9: =H7/SUM($D$7:$T$7) -> 0.16415869 | I9: =I7/SUM($D$7:$T$7) -> 0.072959416 | J9: =J7/SUM($D$7:$T$7) -> 0.021887825 | K9: =K7/SUM($D$7:$T$7) -> 0 | ... T9: =T7/SUM($D$7:$T$7) -> 0
A10: =IF( WEEKDAY(C10)=1,1,) | D10: Weekly tips | V10: Total tip
A11: =IF( WEEKDAY(C11)=1,1,) | D11: =(1-$U$5)*D9*SUM($B$3:$B$5) -> 12.998741 | E11: =(1-$U$5)*E9*SUM($B$3:$B$5) -> 12.998741 | F11: =(1-$U$5)*F9*SUM($B$3:$B$5) -> 12.998741 | G11: =(1-$U$5)*G9*SUM($B$3:$B$5) -> 37.912996 | H11: =(1-$U$5)*H9*SUM($B$3:$B$5) -> 32.496854 | I11: =(1-$U$5)*I9*SUM($B$3:$B$5) -> 14.443046 | J11: =(1-$U$5)*J9*SUM($B$3:$B$5) -> 4.3329138 | K11: =(1-$U$5)*K9*SUM($B$3:$B$5) -> 0 | ... Q11: =(1-$U$5)*Q9*SUM($B$3:$B$5) -> 19.498112 | R11: =(1-$U$5)*R9*SUM($B$3:$B$11) -> 0 | S11: =(1-$U$5)*S9*SUM($B$3:$B$11) -> 0 | T11: =(1-$U$5)*T9*SUM($B$3:$B$11) -> 0 | U11: =IF(A5=1, SUM(B3:B5)*$U$5,) -> 4.04 | V11: =SUM(B3:B5) -> 202
A12: =IF( WEEKDAY(C12)=1,1,) | C12: 45600 | U12: =IF(A6=1, SUM(B4:B6)*$U$5,)
A13: =IF( WEEKDAY(C13)=1,1,) | B13: 105 | C13: 45601 | D13: 4 | E13: 4 | F13: 4 | G13: 7 | H13: 6 | J13: 2 | M13: 4 | N13: 1 | O13: 7 | Q13: 4 | U13: =IF(A7=1, SUM(B5:B7)*$U$5,)
A14: =IF( WEEKDAY(C14)=1,1,) | B14: 75 | C14: 45602 | D14: 2 | E14: 4 | F14: 4 | G14: 7 | H14: 6 | I14: 4 | J14: 2 | K14: 2 | L14: 1 | M14: 4 | N14: 1 | O14: 7 | Q14: 4 | U14: =IF(A8=1, SUM(B6:B8)*$U$5,)
A15: =IF( WEEKDAY(C15)=1,1,) | B15: 72 | C15: 45603 | D15: 4 | F15: 4 | G15: 7 | H15: 6 | I15: 4 | J15: 2 | K15: 1 | M15: 4 | O15: 7 | Q15: 4 | U15: =IF(A9=1, SUM(B7:B9)*$U$5,)
A16: =IF( WEEKDAY(C16)=1,1,) | B16: 63 | C16: 45604 | D16: 4 | F16: 4 | G16: 7 | H16: 6 | I16: 4 | J16: 1 | K16: 1 | L16: 1 | M16: 4 | N16: 1 | O16: 7 | Q16: 4 | U16: =IF(A10=1, SUM(B8:B10)*$U$5,)
A17: =IF( WEEKDAY(C17)=1,1,) | B17: 77 | C17: 45605 | D17: 4 | E17: 4 | F17: 4 | G17: 7 | H17: 6 | M17: 5 | N17: 1 | O17: 5 | Q17: 4 | U17: =IF(A11=1, SUM(B9:B11)*$U$5,)
A18: =IF( WEEKDAY(C18)=1,1,) -> 1 | B18: 64 | C18: 45606 | D18: 4 | E18: 4 | F18: 4 | G18: 7 | H18: 6 | I18: 4 | J18: 2 | M18: 5 | P18: 5 | Q18: 4 | U18: =IF(A12=1, SUM(B10:B12)*$U$5,)
A19: =IF( WEEKDAY(C19)=1,1,) | D19: Points | U19: =IF(A13=1, SUM(B11:B13)*$U$5,)
A20: =IF( WEEKDAY(C20)=1,1,) | D20: =IFERROR(SUM(D12:D18)*HLOOKUP(D$2, $U$2:$Y$3,2,0),) -> 13.2 | E20: =IFERROR(SUM(E12:E18)*HLOOKUP(E$2, $U$2:$Y$3,2,0),) -> 9.6 | F20: =IFERROR(SUM(F12:F18)*HLOOKUP(F$2, $U$2:$Y$3,2,0),) -> 14.4 | G20: =IFERROR(SUM(G12:G18)*HLOOKUP(G$2, $U$2:$Y$3,2,0),) -> 42 | H20: =IFERROR(SUM(H12:H18)*HLOOKUP(H$2, $U$2:$Y$3,2,0),) -> 36 | I20: =IFERROR(SUM(I12:I18)*HLOOKUP(I$2, $U$2:$Y$3,2,0),) -> 16 | J20: =IFERROR(SUM(J12:J18)*HLOOKUP(J$2, $U$2:$Y$3,2,0),) -> 5.4 | K20: =IFERROR(SUM(K12:K18)*HLOOKUP(K$2, $U$2:$Y$3,2,0),) -> 2.4 | ... T20: =IFERROR(SUM(T12:T18)*HLOOKUP(T$2, $U$2:$Y$3,2,0),) -> 0 | U20: =IF(A14=1, SUM(B12:B14)*$U$5,)
A21: =IF( WEEKDAY(C21)=1,1,) | D21: Percent of points | U21: =IF(A15=1, SUM(B13:B15)*$U$5,)
A22: =IF( WEEKDAY(C22)=1,1,) | D22: =IFERROR( D20/SUM($D20:$T20),0) -> 0.058510638 | E22: =IFERROR( E20/SUM($D20:$T20),0) -> 0.042553191 | F22: =IFERROR( F20/SUM($D20:$T20),0) -> 0.063829787 | G22: =IFERROR( G20/SUM($D20:$T20),0) -> 0.18617021 | H22: =IFERROR( H20/SUM($D20:$T20),0) -> 0.15957447 | I22: =IFERROR( I20/SUM($D20:$T20),0) -> 0.070921986 | J22: =IFERROR( J20/SUM($D20:$T20),0) -> 0.02393617 | K22: =IFERROR( K20/SUM($D20:$T20),0) -> 0.010638298 | ... T22: =IFERROR( T20/SUM($D20:$T20),0) -> 0 | U22: =IF(A16=1, SUM(B14:B16)*$U$5,)
A23: =IF( WEEKDAY(C23)=1,1,) | D23: Weekly tips | U23: =IF(A17=1, SUM(B15:B17)*$U$5,) | V23: Total tip
A24: =IF( WEEKDAY(C24)=1,1,) | D24: =(1-$U$5)*D22*SUM($B12:$B18) -> 26.147234 | E24: =(1-$U$5)*E22*SUM($B12:$B18) -> 19.01617 | F24: =(1-$U$5)*F22*SUM($B12:$B18) -> 28.524255 | G24: =(1-$U$5)*G22*SUM($B12:$B18) -> 83.195745 | H24: =(1-$U$5)*H22*SUM($B12:$B18) -> 71.310638 | I24: =(1-$U$5)*I22*SUM($B12:$B18) -> 31.693617 | J24: =(1-$U$5)*J22*SUM($B12:$B18) -> 10.696596 | K24: =(1-$U$5)*K22*SUM($B12:$B18) -> 4.7540426 | ... T24: =(1-$U$5)*T22*SUM($B12:$B18) -> 0 | U24: =IF(A18=1, SUM(B12:B18)*$U$5,) -> 9.12 | V24: =SUM(B13:B18) -> 456
A25: =IF( WEEKDAY(C25)=1,1,) | C25: 45607 | U25: =IF(A19=1, SUM(B13:B19)*$U$5,)
A26: =IF( WEEKDAY(C26)=1,1,) | B26: 82 | C26: 45608 | D26: 5 | E26: 5 | F26: 5 | G26: 7 | H26: 6 | I26: 4 | M26: 4 | O26: 6 | Q26: 4 | R26: 2 | S26: 2 | U26: Cook | V26: Help | W26: Waiter | X26: Waiter/pre | Y26: Cash
A27: =IF( WEEKDAY(C27)=1,1,) | B27: 60 | C27: 45609 | D27: 5 | F27: 5 | G27: 7 | H27: 6 | M27: 4 | O27: 7 | Q27: 4 | R27: 2 | S27: 2 | U27: 0.6 | V27: 0.6 | W27: 0.9 | X27: 1 | Y27: 1
A28: =IF( WEEKDAY(C28)=1,1,) | B28: 80 | C28: 45610 | D28: 5 | E28: 5 | F28: 5 | G28: 7 | H28: 6 | I28: 4 | K28: 2 | L28: 2 | M28: 4 | N28: 1 | O28: 7 | R28: 2 | S28: 2 | U28: Psistaria
A29: =IF( WEEKDAY(C29)=1,1,) | B29: 57 | C29: 45611 | D29: 5 | E29: 5 | F29: 5 | G29: 7 | H29: 6 | I29: 3 | K29: 2 | M29: 4 | N29: 1 | O29: 7 | Q29: 4 | R29: 1 | S29: 2 | U29: 0.02
A30: =IF( WEEKDAY(C30)=1,1,) | B30: 85 | C30: 45612 | D30: 5 | E30: 5 | F30: 5 | G30: 7 | H30: 6 | I30: 4 | M30: 5 | O30: 6 | S30: 2
A31: =IF( WEEKDAY(C31)=1,1,) -> 1 | B31: 75 | C31: 45613 | D31: 5 | E31: 5 | F31: 5 | G31: 7 | H31: 6 | L31: 1 | M31: 5 | O31: 7 | P31: 5 | R31: 2 | S31: 2 | U31: =IF(A25=1, SUM(B19:B25)*$U$5,)
A32: =IF( WEEKDAY(C32)=1,1,) | D32: Points | U32: =IF(A26=1, SUM(B20:B26)*$U$5,)
A33: =IF( WEEKDAY(C33)=1,1,) | D33: =IFERROR(SUM(D25:D31)*HLOOKUP(D$2, $U26:$Y27,2,0),) -> 18 | E33: =IFERROR(SUM(E25:E31)*HLOOKUP(E$2, $U26:$Y27,2,0),) -> 15 | F33: =IFERROR(SUM(F25:F31)*HLOOKUP(F$2, $U26:$Y27,2,0),) -> 18 | G33: =IFERROR(SUM(G25:G31)*HLOOKUP(G$2, $U26:$Y27,2,0),) -> 42 | H33: =IFERROR(SUM(H25:H31)*HLOOKUP(H$2, $U26:$Y27,2,0),) -> 36 | I33: =IFERROR(SUM(I25:I31)*HLOOKUP(I$2, $U26:$Y27,2,0),) -> 15 | J33: =IFERROR(SUM(J25:J31)*HLOOKUP(J$2, $U26:$Y27,2,0),) -> 0 | K33: =IFERROR(SUM(K25:K31)*HLOOKUP(K$2, $U26:$Y27,2,0),) -> 2.4 | ... T33: =IFERROR(SUM(T25:T31)*HLOOKUP(T$2, $U26:$Y27,2,0),) -> 0 | U33: =IF(A27=1, SUM(B21:B27)*$U$5,)
A34: =IF( WEEKDAY(C34)=1,1,) | D34: Percent of points | U34: =IF(A28=1, SUM(B22:B28)*$U$5,)
A35: =IF( WEEKDAY(C35)=1,1,) | D35: =IFERROR( D33/SUM($D33:$T33),) -> 0.073529412 | E35: =IFERROR( E33/SUM($D33:$T33),) -> 0.06127451 | F35: =IFERROR( F33/SUM($D33:$T33),) -> 0.073529412 | G35: =IFERROR( G33/SUM($D33:$T33),) -> 0.17156863 | H35: =IFERROR( H33/SUM($D33:$T33),) -> 0.14705882 | I35: =IFERROR( I33/SUM($D33:$T33),) -> 0.06127451 | J35: =IFERROR( J33/SUM($D33:$T33),) -> 0 | K35: =IFERROR( K33/SUM($D33:$T33),) -> 0.0098039216 | ... T35: =IFERROR( T33/SUM($D33:$T33),) -> 0 | U35: =IF(A29=1, SUM(B23:B29)*$U$5,)
A36: =IF( WEEKDAY(C36)=1,1,) | D36: Weekly tips | U36: =IF(A30=1, SUM(B24:B30)*$U$5,) | V36: Total tip
A37: =IF( WEEKDAY(C37)=1,1,) | D37: =IFERROR((1-$U$5)*D35*SUM($B25:$B31),) -> 31.633824 | E37: =(1-$U$5)*E35*SUM($B25:$B31) -> 26.36152 | F37: =(1-$U$5)*F35*SUM($B25:$B31) -> 31.633824 | G37: =(1-$U$5)*G35*SUM($B25:$B31) -> 73.812255 | H37: =(1-$U$5)*H35*SUM($B25:$B31) -> 63.267647 | I37: =(1-$U$5)*I35*SUM($B25:$B31) -> 26.36152 | J37: =(1-$U$5)*J35*SUM($B25:$B31) -> 0 | K37: =(1-$U$5)*K35*SUM($B25:$B31) -> 4.2178431 | L37: =(1-$U$5)*L35*SUM($B25:$B31) -> 3.1633824 | ... T37: =(1-$U$5)*T35*SUM($B25:$B31) -> 0 | U37: =IF(A31=1, SUM(B25:B31)*$U$5,) -> 8.78 | V37: =SUM(B26:B31) -> 439
A38: =IF( WEEKDAY(C38)=1,1,) | C38: 45614 | U38: =IF(A32=1, SUM(B26:B32)*$U$5,)
A39: =IF( WEEKDAY(C39)=1,1,) | B39: 84 | C39: 45615 | D39: 5 | E39: 5 | F39: 5 | G39: 7 | H39: 6 | I39: 4 | K39: 1 | L39: 4 | M39: 4 | N39: 1 | O39: 7 | R39: 2 | S39: 2 | U39: Cook | V39: Help | W39: Waiter | X39: Waiter/pre | Y39: Cash
A40: =IF( WEEKDAY(C40)=1,1,) | B40: 70 | C40: 45616 | D40: 5 | F40: 5 | G40: 7 | H40: 6 | I40: 4 | L40: 4 | M40: 4 | N40: 1 | O40: 7 | R40: 2 | S40: 2 | U40: 0.6 | V40: 0.6 | W40: 0.9 | X40: 1 | Y40: 1
...

Sheet 2025
B1: Tips | C1: Day | D1: Αναστασία | E1: Αυτάπ | F1: Εύα | G1: Γιάννης | H1: Χριστιάνα | I1: Κρίστης | J1: Ανέλια | K1: Αμάντα | L1: Διομήδης | M1: Παντελίτσα | N1: Μαρία | O1: Τάνια | P1: Ραζβάν | Q1: Σάντρα | S1: Μυρτώ | T1: Κρεμένα | U1: Ψησταριά
A2: =IFERROR( IF( WEEKDAY(C2)=1,1,),) | D2: Cook | E2: Cook | F2: Cook | G2: Waiter/pre | H2: Waiter/pre | I2: Waiter | J2: Waiter/pre | K2: Waiter/pre | L2: Waiter | M2: Cash | N2: Cash | O2: Help | P2: Help | Q2: Help | R2: Waiter/pre | S2: Waiter | T2: Waiter | U2: Cook | V2: Help | W2: Waiter | X2: Waiter/pre | Y2: Cash
A3: =IFERROR( IF( WEEKDAY(C3)=1,1,),) | C3: =DATE(2025,1,1) -> 45658 | U3: 0.6 | V3: 0.6 | W3: 0.9 | X3: 1 | Y3: 1
A4: =IFERROR( IF( WEEKDAY(C4)=1,1,),) | C4: =C3+1 -> 45659 | U4: Psistaria
A5: =IFERROR( IF( WEEKDAY(C5)=1,1,),) | C5: =C4+1 -> 45660 | U5: 0.02
A6: =IFERROR( IF( WEEKDAY(C6)=1,1,),) | C6: =C5+1 -> 45661
A7: =IFERROR( IF( WEEKDAY(C7)=1,1,),) -> 1 | C7: =C6+1 -> 45662
A8: =IFERROR( IF( WEEKDAY(C8)=1,1,),) | C8: Points | D8: =IFERROR(SUM(D3:D7)*HLOOKUP(D2, $U2:$Y3,2,0),) -> 0 | E8: =IFERROR(SUM(E3:E7)*HLOOKUP(E2, $U2:$Y3,2,0),) -> 0 | F8: =IFERROR(SUM(F3:F7)*HLOOKUP(F2, $U2:$Y3,2,0),) -> 0 | G8: =IFERROR(SUM(G3:G7)*HLOOKUP(G2, $U2:$Y3,2,0),) -> 0 | H8: =IFERROR(SUM(H3:H7)*HLOOKUP(H2, $U2:$Y3,2,0),) -> 0 | I8: =IFERROR(SUM(I3:I7)*HLOOKUP(I2, $U2:$Y3,2,0),) -> 0 | J8: =IFERROR(SUM(J3:J7)*HLOOKUP(J2, $U2:$Y3,2,0),) -> 0 | K8: =IFERROR(SUM(K3:K7)*HLOOKUP(K2, $U2:$Y3,2,0),) -> 0 | ... T8: =IFERROR(SUM(T3:T7)*HLOOKUP(T2, $U2:$Y3,2,0),) -> 0
A9: =IFERROR( IF( WEEKDAY(C9)=1,1,),) | C9: % off points | D9: =IFERROR(D8/SUM($D$8:$T$8),0) -> 0 | E9: =IFERROR(E8/SUM($D$8:$T$8),0) -> 0 | F9: =IFERROR(F8/SUM($D$8:$T$8),0) -> 0 | G9: =IFERROR(G8/SUM($D$8:$T$8),0) -> 0 | H9: =IFERROR(H8/SUM($D$8:$T$8),0) -> 0 | I9: =IFERROR(I8/SUM($D$8:$T$8),0) -> 0 | J9: =IFERROR(J8/SUM($D$8:$T$8),0) -> 0 | K9: =IFERROR(K8/SUM($D$8:$T$8),0) -> 0 | ... T9: =IFERROR(T8/SUM($D$8:$T$8),0) -> 0 | U9: Praktiko | V9: Total tip | W9: Theoritiko
A10: =IFERROR( IF( WEEKDAY(C10)=1,1,),) | C10: Weekly tips | D10: =MROUND((1-$U$5)*D9*SUM($B$3:$B$5),5) -> 0 | E10: =MROUND((1-$U$5)*E9*SUM($B$3:$B$5),5) -> 0 | F10: =MROUND((1-$U$5)*F9*SUM($B$3:$B$5),5) -> 0 | G10: =MROUND((1-$U$5)*G9*SUM($B$3:$B$5),5) -> 0 | H10: =MROUND((1-$U$5)*H9*SUM($B$3:$B$5),5) -> 0 | I10: =MROUND((1-$U$5)*I9*SUM($B$3:$B$5),5) -> 0 | J10: =MROUND((1-$U$5)*J9*SUM($B$3:$B$5),5) -> 0 | K10: =MROUND((1-$U$5)*K9*SUM($B$3:$B$5),5) -> 0 | ... T10: =MROUND((1-$U$5)*T9*SUM($B$3:$B$5),5) -> 0 | U10: =V10-SUM(D10:T10) -> 0 | V10: =SUM(B2:B7) -> 0 | W10: =IF(A7=1, SUM(B2:B7)*$U6,) -> 0
A11: =IFERROR( IF( WEEKDAY(C11)=1,1,),) | B11: 60 | C11: =C7+2 -> 45664 | D11: 4 | E11: 4 | F11: 4 | G11: 7 | H11: 6 | K11: 2 | L11: 4 | M11: 4 | O11: 7 | Q11: 1 | R11: 2 | S11: 2
A12: =IFERROR( IF( WEEKDAY(C12)=1,1,),) | B12: 50 | C12: =C11+1 -> 45665 | D12: 4 | E12: 4 | F12: 4 | G12: 7 | H12: 6 | L12: 4 | M12: 4 | O12: 7 | Q12: 1 | R12: 2 | S12: 2 | U12: Cook | V12: Help | W12: Waiter | X12: Waiter/pre | Y12: Cash
A13: =IFERROR( IF( WEEKDAY(C13)=1,1,),) | B13: 75 | C13: =C12+1 -> 45666 | D13: 4 | E13: 4 | F13: 5 | G13: 7 | H13: 6 | I13: 4 | K13: 2 | M13: 4 | O13: 7 | Q13: 2 | R13: 2 | U13: 0.6 | V13: 0.6 | W13: 0.9 | X13: 1 | Y13: 1
A14: =IFERROR( IF( WEEKDAY(C14)=1,1,),) | B14: 105 | C14: =C13+1 -> 45667 | D14: 4 | E14: 4 | F14: 5 | G14: 7 | H14: 6 | I14: 4 | L14: 4 | M14: 4 | O14: 7 | Q14: 2 | R14: 2 | U14: Psistaria
A15: =IFERROR( IF( WEEKDAY(C15)=1,1,),) | B15: 76 | C15: =C14+1 -> 45668 | D15: 4 | E15: 4 | F15: 5 | G15: 7 | H15: 6 | I15: 4 | L15: 4 | M15: 4 | O15: 7 | U15: 0.02
A16: =IFERROR( IF( WEEKDAY(C16)=1,1,),) -> 1 | B16: 113 | C16: =C15+1 -> 45669 | D16: 4 | E16: 4 | F16: 5 | G16: 7 | H16: 6 | L16: 4 | M16: 4 | O16: 7 | R16: 2
A17: =IFERROR( IF( WEEKDAY(C17)=1,1,),) | C17: Points | D17: =IFERROR(SUM(D11:D16)*HLOOKUP(D$2, $U12:$Y13,2,0),) -> 14.4 | E17: =IFERROR(SUM(E11:E16)*HLOOKUP(E$2, $U12:$Y13,2,0),) -> 14.4 | F17: =IFERROR(SUM(F11:F16)*HLOOKUP(F$2, $U12:$Y13,2,0),) -> 16.8 | G17: =IFERROR(SUM(G11:G16)*HLOOKUP(G$2, $U12:$Y13,2,0),) -> 42 | H17: =IFERROR(SUM(H11:H16)*HLOOKUP(H$2, $U12:$Y13,2,0),) -> 36 | I17: =IFERROR(SUM(I11:I16)*HLOOKUP(I$2, $U12:$Y13,2,0),) -> 10.8 | J17: =IFERROR(SUM(J11:J16)*HLOOKUP(J$2, $U12:$Y13,2,0),) -> 0 | K17: =IFERROR(SUM(K11:K16)*HLOOKUP(K$2, $U12:$Y13,2,0),) -> 4 | ... T17: =IFERROR(SUM(T11:T16)*HLOOKUP(T$2, $U12:$Y13,2,0),) -> 0 | U17: =IF(A12=1, SUM(B11:B12)*$U$5,)
A18: =IFERROR( IF( WEEKDAY(C18)=1,1,),) | C18: % off points | D18: =IFERROR( D17/SUM($D17:$T17),0) -> 0.064631957 | E18: =IFERROR( E17/SUM($D17:$T17),0) -> 0.064631957 | F18: =IFERROR( F17/SUM($D17:$T17),0) -> 0.07540395 | G18: =IFERROR( G17/SUM($D17:$T17),0) -> 0.18850987 | H18: =IFERROR( H17/SUM($D17:$T17),0) -> 0.16157989 | I18: =IFERROR( I17/SUM($D17:$T17),0) -> 0.048473968 | J18: =IFERROR( J17/SUM($D17:$T17),0) -> 0 | K18: =IFERROR( K17/SUM($D17:$T17),0) -> 0.017953321 | ... T18: =IFERROR( T17/SUM($D17:$T17),0) -> 0 | U18: Praktiko | V18: Total tip | W18: Theoritiko
A19: =IFERROR( IF( WEEKDAY(C19)=1,1,),) | C19: Weekly tips | D19: =MROUND((1-$U15)*D18*SUM($B11:$B16),5) -> 30 | E19: =MROUND((1-$U15)*E18*SUM($B11:$B16),5) -> 30 | F19: =MROUND((1-$U15)*F18*SUM($B11:$B16),5) -> 35 | G19: =MROUND((1-$U15)*G18*SUM($B11:$B16),5) -> 90 | H19: =MROUND((1-$U15)*H18*SUM($B11:$B16),5) -> 75 | I19: =MROUND((1-$U15)*I18*SUM($B11:$B16),5) -> 25 | J19: =MROUND((1-$U15)*J18*SUM($B11:$B16),5) -> 0 | K19: =MROUND((1-$U15)*K18*SUM($B11:$B16),5) -> 10 | ... T19: =MROUND((1-$U15)*T18*SUM($B11:$B16),5) -> 0 | U19: =V19-SUM(D19:T19) -> -1 | V19: =SUM(B11:B16) -> 479 | W19: =IF(A16=1, SUM(B11:B16)*$U15,) -> 9.58
A20: =IFERROR( IF( WEEKDAY(C20)=1,1,),) | B20: 58 | C20: =C16+2 -> 45671 | D20: 5 | E20: 5 | F20: 6 | G20: 7 | H20: 6 | M20: 4 | O20: 7 | P20: 1 | Q20: 2 | R20: 2
A21: =IFERROR( IF( WEEKDAY(C21)=1,1,),) | B21: 95 | C21: =C20+1 -> 45672 | D21: 5 | E21: 5 | F21: 6 | G21: 7 | H21: 6 | K21: 2 | M21: 4 | O21: 7 | P21: 2 | Q21: 3 | R21: 2 | U21: Cook | V21: Help | W21: Waiter | X21: Waiter/pre | Y21: Cash
A22: =IFERROR( IF( WEEKDAY(C22)=1,1,),) | B22: 70 | C22: =C21+1 -> 45673 | D22: 5 | E22: 5 | F22: 6 | G22: 7 | H22: 6 | I22: 4 | L22: 4 | M22: 4 | O22: 7 | Q22: 2 | R22: 2 | U22: 0.6 | V22: 0.6 | W22: 0.9 | X22: 1 | Y22: 1
A23: =IFERROR( IF( WEEKDAY(C23)=1,1,),) | B23: 105 | C23: =C22+1 -> 45674 | D23: 5 | E23: 5 | F23: 6 | G23: 7 | H23: 6 | I23: 4 | L23: 4 | M23: 4 | O23: 7 | Q23: 2 | R23: 2 | U23: Psistaria
A24: =IFERROR( IF( WEEKDAY(C24)=1,1,),) | B24: 75 | C24: =C23+1 -> 45675 | D24: 5 | E24: 5 | F24: 6 | G24: 7 | H24: 6 | I24: 4 | L24: 4 | M24: 4 | O24: 7 | U24: 0.04
A25: =IFERROR( IF( WEEKDAY(C25)=1,1,),) -> 1 | B25: 70 | C25: =C24+1 -> 45676 | D25: 5 | E25: 5 | F25: 6 | G25: 7 | H25: 6 | I25: 4 | L25: 4 | M25: 4 | P25: 6 | Q25: 2 | R25: 2
A26: =IFERROR( IF( WEEKDAY(C26)=1,1,),) | C26: Points | D26: =IFERROR(SUM(D20:D25)*HLOOKUP(D$2, $U21:$Y22,2,0),) -> 18 | E26: =IFERROR(SUM(E20:E25)*HLOOKUP(E$2, $U21:$Y22,2,0),) -> 18 | F26: =IFERROR(SUM(F20:F25)*HLOOKUP(F$2, $U21:$Y22,2,0),) -> 21.6 | G26: =IFERROR(SUM(G20:G25)*HLOOKUP(G$2, $U21:$Y22,2,0),) -> 42 | H26: =IFERROR(SUM(H20:H25)*HLOOKUP(H$2, $U21:$Y22,2,0),) -> 36 | I26: =IFERROR(SUM(I20:I25)*HLOOKUP(I$2, $U21:$Y22,2,0),) -> 14.4 | J26: =IFERROR(SUM(J20:J25)*HLOOKUP(J$2, $U21:$Y22,2,0),) -> 0 | K26: =IFERROR(SUM(K20:K25)*HLOOKUP(K$2, $U21:$Y22,2,0),) -> 2 | ... T26: =IFERROR(SUM(T20:T25)*HLOOKUP(T$2, $U21:$Y22,2,0),) -> 0 | U26: =IF(A21=1, SUM(B20:B21)*$U$5,)
A27: =IFERROR( IF( WEEKDAY(C27)=1,1,),) | C27: % off points | D27: =IFERROR( D26/SUM($D26:$T26),0) -> 0.077120823 | E27: =IFERROR( E26/SUM($D26:$T26),0) -> 0.077120823 | F27: =IFERROR( F26/SUM($D26:$T26),0) -> 0.092544987 | G27: =IFERROR( G26/SUM($D26:$T26),0) -> 0.17994859 | H27: =IFERROR( H26/SUM($D26:$T26),0) -> 0.15424165 | I27: =IFERROR( I26/SUM($D26:$T26),0) -> 0.061696658 | J27: =IFERROR( J26/SUM($D26:$T26),0) -> 0 | K27: =IFERROR( K26/SUM($D26:$T26),0) -> 0.0085689803 | ... T27: =IFERROR( T26/SUM($D26:$T26),0) -> 0 | U27: Praktiko | V27: Total tip | W27: Theoritiko
A28: =IFERROR( IF( WEEKDAY(C28)=1,1,),) | C28: Weekly tips | D28: =MROUND((1-$U24)*D27*SUM($B20:$B25),5) -> 35 | E28: =MROUND((1-$U24)*E27*SUM($B20:$B25),5) -> 35 | F28: =MROUND((1-$U24)*F27*SUM($B20:$B25),5) -> 40 | G28: =MROUND((1-$U24)*G27*SUM($B20:$B25),5) -> 80 | H28: =MROUND((1-$U24)*H27*SUM($B20:$B25),5) -> 70 | I28: =MROUND((1-$U24)*I27*SUM($B20:$B25),5) -> 30 | J28: =MROUND((1-$U24)*J27*SUM($B20:$B25),5) -> 0 | K28: =MROUND((1-$U24)*K27*SUM($B20:$B25),5) -> 5 | ... T28: =MROUND((1-$U24)*T27*SUM($B20:$B25),5) -> 0 | U28: =V28-SUM(D28:T28) -> 18 | V28: =SUM(B20:B25) -> 473 | W28: =IF(A25=1, SUM(B20:B25)*$U24,) -> 18.92
A29: =IFERROR( IF( WEEKDAY(C29)=1,1,),) | B29: 75 | C29: =C25+2 -> 45678 | D29: 5 | E29: 5 | F29: 6 | G29: 7 | H29: 6 | I29: 4 | L29: 4 | M29: 4 | O29: 7 | Q29: 3 | R29: 2
A30: =IFERROR( IF( WEEKDAY(C30)=1,1,),) | B30: 47 | C30: =C29+1 -> 45679 | D30: 5 | F30: 6 | G30: 7 | H30: 6 | L30: 4 | M30: 4 | O30: 7 | Q30: 2 | R30: 2 | U30: Cook | V30: Help | W30: Waiter | X30: Waiter/pre | Y30: Cash
A31: =IFERROR( IF( WEEKDAY(C31)=1,1,),) | B31: 74 | C31: =C30+1 -> 45680 | D31: 5 | E31: 5 | F31: 6 | G31: 7 | H31: 6 | I31: 4 | L31: 4 | M31: 4 | O31: 7 | Q31: 3 | R31: 2 | U31: 0.6 | V31: 0.6 | W31: 0.9 | X31: 1 | Y31: 1
A32: =IFERROR( IF( WEEKDAY(C32)=1,1,),) | B32: 116 | C32: =C31+1 -> 45681 | D32: 5 | F32: 6 | G32: 7 | H32: 6 | L32: 4 | M32: 4 | O32: 7 | Q32: 4 | R32: 2 | U32: Psistaria
A33: =IFERROR( IF( WEEKDAY(C33)=1,1,),) | B33: 86 | C33: =C32+1 -> 45682 | D33: 5 | E33: 5 | F33: 6 | G33: 7 | H33: 6 | I33: 4 | L33: 4 | M33: 4 | O33: 7 | P33: 2 | U33: 0.04
A34: =IFERROR( IF( WEEKDAY(C34)=1,1,),) -> 1 | B34: 103 | C34: =C33+1 -> 45683 | D34: 5 | E34: 5 | F34: 6 | G34: 7 | H34: 6 | I34: 4 | L34: 4 | M34: 4 | P34: 6 | Q34: 4 | R34: 2
A35: =IFERROR( IF( WEEKDAY(C35)=1,1,),) | C35: Points | D35: =IFERROR(SUM(D29:D34)*HLOOKUP(D$2, $U30:$Y31,2,0),) -> 18 | E35: =IFERROR(SUM(E29:E34)*HLOOKUP(E$2, $U30:$Y31,2,0),) -> 12 | F35: =IFERROR(SUM(F29:F34)*HLOOKUP(F$2, $U30:$Y31,2,0),) -> 21.6 | G35: =IFERROR(SUM(G29:G34)*HLOOKUP(G$2, $U30:$Y31,2,0),) -> 42 | H35: =IFERROR(SUM(H29:H34)*HLOOKUP(H$2, $U30:$Y31,2,0),) -> 36 | I35: =IFERROR(SUM(I29:I34)*HLOOKUP(I$2, $U30:$Y31,2,0),) -> 14.4 | J35: =IFERROR(SUM(J29:J34)*HLOOKUP(J$2, $U30:$Y31,2,0),) -> 0 | K35: =IFERROR(SUM(K29:K34)*HLOOKUP(K$2, $U30:$Y31,2,0),) -> 0 | ... T35: =IFERROR(SUM(T29:T34)*HLOOKUP(T$2, $U30:$Y31,2,0),) -> 0 | U35: =IF(A30=1, SUM(B29:B30)*$U$5,)
A36: =IFERROR( IF( WEEKDAY(C36)=1,1,),) | C36: % off points | D36: =IFERROR( D35/SUM($D35:$T35),0) -> 0.076595745 | E36: =IFERROR( E35/SUM($D35:$T35),0) -> 0.05106383 | F36: =IFERROR( F35/SUM($D35:$T35),0) -> 0.091914894 | G36: =IFERROR( G35/SUM($D35:$T35),0) -> 0.1787234 | H36: =IFERROR( H35/SUM($D35:$T35),0) -> 0.15319149 | I36: =IFERROR( I35/SUM($D35:$T35),0) -> 0.061276596 | J36: =IFERROR( J35/SUM($D35:$T35),0) -> 0 | K36: =IFERROR( K35/SUM($D35:$T35),0) -> 0 | ... T36: =IFERROR( T35/SUM($D35:$T35),0) -> 0 | U36: Praktiko | V36: Total tip | W36: Theoritiko
A37: =IFERROR( IF( WEEKDAY(C37)=1,1,),) | C37: Weekly tips | D37: =MROUND((1-$U33)*D36*SUM($B29:$B34),5) -> 35 | E37: =MROUND((1-$U33)*E36*SUM($B29:$B34),5) -> 25 | F37: =MROUND((1-$U33)*F36*SUM($B29:$B34),5) -> 45 | G37: =MROUND((1-$U33)*G36*SUM($B29:$B34),5) -> 85 | H37: =MROUND((1-$U33)*H36*SUM($B29:$B34),5) -> 75 | I37: =MROUND((1-$U33)*I36*SUM($B29:$B34),5) -> 30 | J37: =MROUND((1-$U33)*J36*SUM($B29:$B34),5) -> 0 | K37: =MROUND((1-$U33)*K36*SUM($B29:$B34),5) -> 0 | ... T37: =MROUND((1-$U33)*T36*SUM($B29:$B34),5) -> 0 | U37: =V37-SUM(D37:T37) -> 16 | V37: =SUM(B29:B34) -> 501 | W37: =IF(A34=1, SUM(B29:B34)*$U33,) -> 20.04
A38: =IFERROR( IF( WEEKDAY(C38)=1,1,),) | B38: 59 | C38: =C34+2 -> 45685 | D38: 5 | F38: 6 | G38: 7 | H38: 6 | L38: 4 | M38: 4 | O38: 7 | P38: 1 | Q38: 3 | R38: 2
A39: =IFERROR( IF( WEEKDAY(C39)=1,1,),) | B39: 79 | C39: =C38+1 -> 45686 | D39: 5 | F39: 6 | G39: 7 | H39: 6 | I39: 4 | K39: 1 | M39: 4 | O39: 7 | Q39: 3 | R39: 2 | U39: Cook | V39: Help | W39: Waiter | X39: Waiter/pre | Y39: Cash
A40: =IFERROR( IF( WEEKDAY(C40)=1,1,),) | B40: 71 | C40: =C39+1 -> 45687 | D40: 5 | E40: 5 | F40: 6 | G40: 7 | H40: 6 | I40: 4 | L40: 4 | M40: 4 | O40: 7 | P40: 1 | Q40: 2 | R40: 2 | U40: 0.6 | V40: 0.6 | W40: 0.9 | X40: 1 | Y40: 1
...

Sheet WeightRole
A1: Dates | B1: Αναστασία | C1: Αυτάπ | D1: Εύα | E1: Γιάννης | F1: Χριστιάνα | G1: Κρίστης | H1: Γκάμπριελ | I1: Τάνια | J1: Μαρίνα | K1: Ανέλια | L1: Ναταλία | M1: Παντελίτσα | N1: Μαρία | O1: Διομήδης | P1: Αμάντα | Q1: Ανθούλα | R1: Ραζβάν | S1: Σάντρα | T1: Κρεμένα | U1: Μυρτώ | V1: Λαουρέντζο | W1: Μαρήλια | X1: Μαίρη | Y1: Γκαλίνα | Z1: Μαίρη Ιεαχωβά | AA1: Χριστίνα | AB1: Καλομοίρα | AC1: Χασάν | AD1: Σοφία
A2: 45597 | B2: 0.6 | C2: 0.6 | D2: 0.6 | E2: 1 | F2: 1 | G2: 1 | H2: 0.6 | I2: 0.6 | J2: 0.6 | K2: 0.9 | L2: 0.6 | M2: 1 | N2: 1 | O2: 0.9 | P2: 1 | Q2: 0.6 | R2: 0.6 | S2: 0.6 | T2: 0.6 | U2: 0.6 | V2: 0.6 | W2: 0.6 | X2: 0.6 | Y2: 0.6
A3: =A2+1 -> 45598 | B3: 0.6 | C3: 0.6 | D3: 0.6 | E3: 1 | F3: 1 | G3: 1 | H3: 0.6 | I3: 0.6 | J3: 0.6 | K3: 0.9 | L3: 0.6 | M3: 1 | N3: 1 | O3: 0.9 | P3: 1 | Q3: 0.6 | R3: 0.6 | S3: 0.6 | T3: 0.6 | U3: 0.6 | V3: 0.6 | W3: 0.6 | X3: 0.6 | Y3: 0.6
A4: =A3+1 -> 45599 | B4: 0.6 | C4: 0.6 | D4: 0.6 | E4: 1 | F4: 1 | G4: 1 | H4: 0.6 | I4: 0.6 | J4: 0.6 | K4: 0.9 | L4: 0.6 | M4: 1 | N4: 1 | O4: 0.9 | P4: 1 | Q4: 0.6 | R4: 0.6 | S4: 0.6 | T4: 0.6 | U4: 0.6 | V4: 0.6 | W4: 0.6 | X4: 0.6 | Y4: 0.6
A5: =A4+1 -> 45600 | B5: 0.6 | C5: 0.6 | D5: 0.6 | E5: 1 | F5: 1 | G5: 1 | H5: 0.6 | I5: 0.6 | J5: 0.6 | K5: 0.9 | L5: 0.6 | M5: 1 | N5: 1 | O5: 0.9 | P5: 1 | Q5: 0.6 | R5: 0.6 | S5: 0.6 | T5: 0.6 | U5: 0.6 | V5: 0.6 | W5: 0.6 | X5: 0.6 | Y5: 0.6
A6: =A5+1 -> 45601 | B6: 0.6 | C6: 0.6 | D6: 0.6 | E6: 1 | F6: 1 | G6: 1 | H6: 0.6 | I6: 0.6 | J6: 0.6 | K6: 0.9 | L6: 0.6 | M6: 1 | N6: 1 | O6: 0.9 | P6: 1 | Q6: 0.6 | R6: 0.6 | S6: 0.6 | T6: 0.6 | U6: 0.6 | V6: 0.6 | W6: 0.6 | X6: 0.6 | Y6: 0.6
A7: =A6+1 -> 45602 | B7: 0.6 | C7: 0.6 | D7: 0.6 | E7: 1 | F7: 1 | G7: 1 | H7: 0.6 | I7: 0.6 | J7: 0.6 | K7: 0.9 | L7: 0.6 | M7: 1 | N7: 1 | O7: 0.9 | P7: 1 | Q7: 0.6 | R7: 0.6 | S7: 0.6 | T7: 0.6 | U7: 0.6 | V7: 0.6 | W7: 0.6 | X7: 0.6 | Y7: 0.6
A8: =A7+1 -> 45603 | B8: 0.6 | C8: 0.6 | D8: 0.6 | E8: 1 | F8: 1 | G8: 1 | H8: 0.6 | I8: 0.6 | J8: 0.6 | K8: 0.9 | L8: 0.6 | M8: 1 | N8: 1 | O8: 0.9 | P8: 1 | Q8: 0.6 | R8: 0.6 | S8: 0.6 | T8: 0.6 | U8: 0.6 | V8: 0.6 | W8: 0.6 | X8: 0.6 | Y8: 0.6
A9: =A8+1 -> 45604 | B9: 0.6 | C9: 0.6 | D9: 0.6 | E9: 1 | F9: 1 | G9: 1 | H9: 0.6 | I9: 0.6 | J9: 0.6 | K9: 0.9 | L9: 0.6 | M9: 1 | N9: 1 | O9: 0.9 | P9: 1 | Q9: 0.6 | R9: 0.6 | S9: 0.6 | T9: 0.6 | U9: 0.6 | V9: 0.6 | W9: 0.6 | X9: 0.6 | Y9: 0.6
A10: =A9+1 -> 45605 | B10: 0.6 | C10: 0.6 | D10: 0.6 | E10: 1 | F10: 1 | G10: 1 | H10: 0.6 | I10: 0.6 | J10: 0.6 | K10: 0.9 | L10: 0.6 | M10: 1 | N10: 1 | O10: 0.9 | P10: 1 | Q10: 0.6 | R10: 0.6 | S10: 0.6 | T10: 0.6 | U10: 0.6 | V10: 0.6 | W10: 0.6 | X10: 0.6 | Y10: 0.6
A11: =A10+1 -> 45606 | B11: 0.6 | C11: 0.6 | D11: 0.6 | E11: 1 | F11: 1 | G11: 1 | H11: 0.6 | I11: 0.6 | J11: 0.6 | K11: 0.9 | L11: 0.6 | M11: 1 | N11: 1 | O11: 0.9 | P11: 1 | Q11: 0.6 | R11: 0.6 | S11: 0.6 | T11: 0.6 | U11: 0.6 | V11: 0.6 | W11: 0.6 | X11: 0.6 | Y11: 0.6
A12: =A11+1 -> 45607 | B12: 0.6 | C12: 0.6 | D12: 0.6 | E12: 1 | F12: 1 | G12: 1 | H12: 0.6 | I12: 0.6 | J12: 0.6 | K12: 0.9 | L12: 0.6 | M12: 1 | N12: 1 | O12: 0.9 | P12: 1 | Q12: 0.6 | R12: 0.6 | S12: 0.6 | T12: 0.6 | U12: 0.6 | V12: 0.6 | W12: 0.6 | X12: 0.6 | Y12: 0.6
A13: =A12+1 -> 45608 | B13: 0.6 | C13: 0.6 | D13: 0.6 | E13: 1 | F13: 1 | G13: 1 | H13: 0.6 | I13: 0.6 | J13: 0.6 | K13: 0.9 | L13: 0.6 | M13: 1 | N13: 1 | O13: 0.9 | P13: 1 | Q13: 0.6 | R13: 0.6 | S13: 0.6 | T13: 0.6 | U13: 0.6 | V13: 0.6 | W13: 0.6 | X13: 0.6 | Y13: 0.6
A14: =A13+1 -> 45609 | B14: 0.6 | C14: 0.6 | D14: 0.6 | E14: 1 | F14: 1 | G14: 1 | H14: 0.6 | I14: 0.6 | J14: 0.6 | K14: 0.9 | L14: 0.6 | M14: 1 | N14: 1 | O14: 0.9 | P14: 1 | Q14: 0.6 | R14: 0.6 | S14: 0.6 | T14: 0.6 | U14: 0.6 | V14: 0.6 | W14: 0.6 | X14: 0.6 | Y14: 0.6
... A336: =A335+1 -> 45931 | B336: 0.6 | C336: 0.6 | D336: 0.6 | E336: 1 | F336: 1 | G336: 1 | H336: 0.6 | I336: 0.6 | J336: 0.6 | K336: 0.9 | L336: 0.6 | M336: 1 | N336: 1 | O336: 0.9 | P336: 1 | Q336: 0.6 | R336: 0.6 | S336: 0.6 | T336: 0.6 | U336: 0.6 | V336: 0.6 | W336: 0.6 | X336: 0.6 | Y336: 0.6
A337: =A336+1 -> 45932 | B337: 0.6 | C337: 0.6 | D337: 0.6 | E337: 1 | F337: 1 | G337: 1 | H337: 0.6 | I337: 0.6 | J337: 0.6 | K337: 0.9 | L337: 0.6 | M337: 1 | N337: 1 | O337: 0.9 | P337: 1 | Q337: 0.6 | R337: 0.6 | S337: 0.6 | T337: 0.6 | U337: 0.6 | V337: 0.6 | W337: 0.6 | X337: 0.6 | Y337: 0.6 | Z337: 0.6 | AA337: 0.6 | AB337: 0.6 | AC337: 0.6 | AD337: 0.9
A338: =A337+1 -> 45933 | B338: 0.6 | C338: 0.6 | D338: 0.6 | E338: 1 | F338: 1 | G338: 1 | H338: 0.6 | I338: 0.6 | J338: 0.6 | K338: 0.9 | L338: 0.6 | M338: 1 | N338: 1 | O338: 0.9 | P338: 1 | Q338: 0.6 | R338: 0.6 | S338: 0.6 | T338: 0.6 | U338: 0.6 | V338: 0.6 | W338: 0.6 | X338: 0.6 | Y338: 0.6 | Z338: 0.6 | AA338: 0.6 | AB338: 0.6 | AC338: 0.6 | AD338: 0.9
A339: =A338+1 -> 45934 | B339: 0.6 | C339: 0.6 | D339: 0.6 | E339: 1 | F339: 1 | G339: 1 | H339: 0.6 | I339: 0.6 | J339: 0.6 | K339: 0.9 | L339: 0.6 | M339: 1 | N339: 1 | O339: 0.9 | P339: 1 | Q339: 0.6 | R339: 0.6 | S339: 0.6 | T339: 0.6 | U339: 0.6 | V339: 0.6 | W339: 0.6 | X339: 0.6 | Y339: 0.6 | Z339: 0.6 | AA339: 0.6 | AB339: 0.6 | AC339: 0.6 | AD339: 0.9
A340: =A339+1 -> 45935 | B340: 0.6 | C340: 0.6 | D340: 0.6 | E340: 1 | F340: 1 | G340: 1 | H340: 0.6 | I340: 0.6 | J340: 0.6 | K340: 0.9 | L340: 0.6 | M340: 1 | N340: 1 | O340: 0.9 | P340: 1 | Q340: 0.6 | R340: 0.6 | S340: 0.6 | T340: 0.6 | U340: 0.6 | V340: 0.6 | W340: 0.6 | X340: 0.6 | Y340: 0.6 | Z340: 0.6 | AA340: 0.6 | AB340: 0.6 | AC340: 0.6 | AD340: 0.9
A341: =A340+1 -> 45936 | B341: 0.6 | C341: 0.6 | D341: 0.6 | E341: 1 | F341: 1 | G341: 1 | H341: 0.6 | I341: 0.6 | J341: 0.6 | K341: 0.9 | L341: 0.6 | M341: 1 | N341: 1 | O341: 0.9 | P341: 1 | Q341: 0.6 | R341: 0.6 | S341: 0.6 | T341: 0.6 | U341: 0.6 | V341: 0.6 | W341: 0.6 | X341: 0.6 | Y341: 0.6 | Z341: 0.6 | AA341: 0.6 | AB341: 0.6 | AC341: 0.6 | AD341: 0.9
A342: =A341+1 -> 45937 | B342: 0.6 | C342: 0.6 | D342: 0.6 | E342: 1 | F342: 1 | G342: 1 | H342: 0.6 | I342: 0.6 | J342: 0.6 | K342: 0.9 | L342: 0.6 | M342: 1 | N342: 1 | O342: 0.9 | P342: 1 | Q342: 0.6 | R342: 0.6 | S342: 0.6 | T342: 0.6 | U342: 0.6 | V342: 0.6 | W342: 0.6 | X342: 0.6 | Y342: 0.6 | Z342: 0.6 | AA342: 0.6 | AB342: 0.6 | AC342: 0.6 | AD342: 0.9
A343: =A342+1 -> 45938 | B343: 0.6 | C343: 0.6 | D343: 0.6 | E343: 1 | F343: 1 | G343: 1 | H343: 0.6 | I343: 0.6 | J343: 0.6 | K343: 0.9 | L343: 0.6 | M343: 1 | N343: 1 | O343: 0.9 | P343: 1 | Q343: 0.6 | R343: 0.6 | S343: 0.6 | T343: 0.6 | U343: 0.6 | V343: 0.6 | W343: 0.6 | X343: 0.6 | Y343: 0.6 | Z343: 0.6 | AA343: 0.6 | AB343: 0.6 | AC343: 0.6 | AD343: 0.9
A344: =A343+1 -> 45939 | B344: 0.6 | C344: 0.6 | D344: 0.6 | E344: 1 | F344: 1 | G344: 1 | H344: 0.6 | I344: 0.6 | J344: 0.6 | K344: 0.9 | L344: 0.6 | M344: 1 | N344: 1 | O344: 0.9 | P344: 1 | Q344: 0.6 | R344: 0.6 | S344: 0.6 | T344: 0.6 | U344: 0.6 | V344: 0.6 | W344: 0.6 | X344: 0.6 | Y344: 0.6 | Z344: 0.6 | AA344: 0.6 | AB344: 0.6 | AC344: 0.6 | AD344: 0.9
A345: =A344+1 -> 45940 | B345: 0.6 | C345: 0.6 | D345: 0.6 | E345: 1 | F345: 1 | G345: 1 | H345: 0.6 | I345: 0.6 | J345: 0.6 | K345: 0.9 | L345: 0.6 | M345: 1 | N345: 1 | O345: 0.9 | P345: 1 | Q345: 0.6 | R345: 0.6 | S345: 0.6 | T345: 0.6 | U345: 0.6 | V345: 0.6 | W345: 0.6 | X345: 0.6 | Y345: 0.6 | Z345: 0.6 | AA345: 0.6 | AB345: 0.6 | AC345: 0.6 | AD345: 0.9
A346: =A345+1 -> 45941 | B346: 0.6 | C346: 0.6 | D346: 0.6 | E346: 1 | F346: 1 | G346: 1 | H346: 0.6 | I346: 0.6 | J346: 0.6 | K346: 0.9 | L346: 0.6 | M346: 1 | N346: 1 | O346: 0.9 | P346: 1 | Q346: 0.6 | R346: 0.6 | S346: 0.6 | T346: 0.6 | U346: 0.6 | V346: 0.6 | W346: 0.6 | X346: 0.6 | Y346: 0.6 | Z346: 0.6 | AA346: 0.6 | AB346: 0.6 | AC346: 0.6 | AD346: 0.9
A347: =A346+1 -> 45942 | B347: 0.6 | C347: 0.6 | D347: 0.6 | E347: 1 | F347: 1 | G347: 1 | H347: 0.6 | I347: 0.6 | J347: 0.6 | K347: 0.9 | L347: 0.6 | M347: 1 | N347: 1 | O347: 0.9 | P347: 1 | Q347: 0.6 | R347: 0.6 | S347: 0.6 | T347: 0.6 | U347: 0.6 | V347: 0.6 | W347: 0.6 | X347: 0.6 | Y347: 0.6 | Z347: 0.6 | AA347: 0.6 | AB347: 0.6 | AC347: 0.6 | AD347: 0.9
A348: =A347+1 -> 45943 | B348: 0.6 | C348: 0.6 | D348: 0.6 | E348: 1 | F348: 1 | G348: 1 | H348: 0.6 | I348: 0.6 | J348: 0.6 | K348: 0.9 | L348: 0.6 | M348: 1 | N348: 1 | O348: 0.9 | P348: 1 | Q348: 0.6 | R348: 0.6 | S348: 0.6 | T348: 0.6 | U348: 0.6 | V348: 0.6 | W348: 0.6 | X348: 0.6 | Y348: 0.6 | Z348: 0.6 | AA348: 0.6 | AB348: 0.6 | AC348: 0.6 | AD348: 0.9
... A621: =A620+1 -> 46216 | B621: 0.6 | C621: 0.6 | D621: 0.6 | E621: 1 | F621: 1 | G621: 1 | H621: 0.6 | I621: 0.6 | J621: 0.6 | K621: 0.9 | L621: 0.6 | M621: 1 | N621: 1 | O621: 0.9 | P621: 1 | Q621: 0.6 | R621: 0.6 | S621: 0.6 | T621: 0.6 | U621: 0.6 | V621: 0.6 | W621: 0.6 | X621: 0.6 | Y621: 0.6 | Z621: 0.6 | AA621: 0.6 | AB621: 1 | AC621: 0.6 | AD621: 0.9
A622: =A621+1 -> 46217 | B622: =IFERROR( Hours!D622/SUM(Hours!$D622:$Z622),) | C622: =IFERROR( Hours!F622/SUM(Hours!$D622:$Z622),) | D622: =IFERROR( Hours!G622/SUM(Hours!$D622:$Z622),) | E622: =IFERROR( Hours!C622/SUM(Hours!$D622:$Z622),) | F622: =IFERROR( Hours!H622/SUM(Hours!$D622:$Z622),) | G622: =IFERROR( Hours!I622/SUM(Hours!$D622:$Z622),) | H622: =IFERROR( Hours!J622/SUM(Hours!$D622:$Z622),) | I622: =IFERROR( Hours!K622/SUM(Hours!$D622:$Z622),) | J622: =IFERROR( Hours!L622/SUM(Hours!$D622:$Z622),) | K622: =IFERROR( Hours!M622/SUM(Hours!$D622:$Z622),) | L622: =IFERROR( Hours!N622/SUM(Hours!$D622:$Z622),) | M622: =IFERROR( Hours!B622/SUM(Hours!$D622:$Z622),) | N622: =IFERROR( Hours!O622/SUM(Hours!$D622:$Z622),) | O622: =IFERROR( Hours!E622/SUM(Hours!$D622:$Z622),) | P622: =IFERROR( Hours!P622/SUM(Hours!$D622:$Z622),) | Q622: =IFERROR( Hours!Q622/SUM(Hours!$D622:$Z622),) | R622: =IFERROR( Hours!R622/SUM(Hours!$D622:$Z622),) | S622: =IFERROR( Hours!S622/SUM(Hours!$D622:$Z622),)
A623: =A622+1 -> 46218 | B623: =IFERROR( Hours!D623/SUM(Hours!$D623:$Z623),) | C623: =IFERROR( Hours!F623/SUM(Hours!$D623:$Z623),) | D623: =IFERROR( Hours!G623/SUM(Hours!$D623:$Z623),) | E623: =IFERROR( Hours!C623/SUM(Hours!$D623:$Z623),) | F623: =IFERROR( Hours!H623/SUM(Hours!$D623:$Z623),) | G623: =IFERROR( Hours!I623/SUM(Hours!$D623:$Z623),) | H623: =IFERROR( Hours!J623/SUM(Hours!$D623:$Z623),) | I623: =IFERROR( Hours!K623/SUM(Hours!$D623:$Z623),) | J623: =IFERROR( Hours!L623/SUM(Hours!$D623:$Z623),) | K623: =IFERROR( Hours!M623/SUM(Hours!$D623:$Z623),) | L623: =IFERROR( Hours!N623/SUM(Hours!$D623:$Z623),) | M623: =IFERROR( Hours!B623/SUM(Hours!$D623:$Z623),) | N623: =IFERROR( Hours!O623/SUM(Hours!$D623:$Z623),) | O623: =IFERROR( Hours!E623/SUM(Hours!$D623:$Z623),) | P623: =IFERROR( Hours!P623/SUM(Hours!$D623:$Z623),) | Q623: =IFERROR( Hours!Q623/SUM(Hours!$D623:$Z623),) | R623: =IFERROR( Hours!R623/SUM(Hours!$D623:$Z623),) | S623: =IFERROR( Hours!S623/SUM(Hours!$D623:$Z623),)
A624: =A623+1 -> 46219 | B624: =IFERROR( Hours!D624/SUM(Hours!$D624:$Z624),) | C624: =IFERROR( Hours!F624/SUM(Hours!$D624:$Z624),) | D624: =IFERROR( Hours!G624/SUM(Hours!$D624:$Z624),) | E624: =IFERROR( Hours!C624/SUM(Hours!$D624:$Z624),) | F624: =IFERROR( Hours!H624/SUM(Hours!$D624:$Z624),) | G624: =IFERROR( Hours!I624/SUM(Hours!$D624:$Z624),) | H624: =IFERROR( Hours!J624/SUM(Hours!$D624:$Z624),) | I624: =IFERROR( Hours!K624/SUM(Hours!$D624:$Z624),) | J624: =IFERROR( Hours!L624/SUM(Hours!$D624:$Z624),) | K624: =IFERROR( Hours!M624/SUM(Hours!$D624:$Z624),) | L624: =IFERROR( Hours!N624/SUM(Hours!$D624:$Z624),) | M624: =IFERROR( Hours!B624/SUM(Hours!$D624:$Z624),) | N624: =IFERROR( Hours!O624/SUM(Hours!$D624:$Z624),) | O624: =IFERROR( Hours!E624/SUM(Hours!$D624:$Z624),) | P624: =IFERROR( Hours!P624/SUM(Hours!$D624:$Z624),) | Q624: =IFERROR( Hours!Q624/SUM(Hours!$D624:$Z624),) | R624: =IFERROR( Hours!R624/SUM(Hours!$D624:$Z624),) | S624: =IFERROR( Hours!S624/SUM(Hours!$D624:$Z624),)
A625: =A624+1 -> 46220 | B625: =IFERROR( Hours!D625/SUM(Hours!$D625:$Z625),) | C625: =IFERROR( Hours!F625/SUM(Hours!$D625:$Z625),) | D625: =IFERROR( Hours!G625/SUM(Hours!$D625:$Z625),) | E625: =IFERROR( Hours!C625/SUM(Hours!$D625:$Z625),) | F625: =IFERROR( Hours!H625/SUM(Hours!$D625:$Z625),) | G625: =IFERROR( Hours!I625/SUM(Hours!$D625:$Z625),) | H625: =IFERROR( Hours!J625/SUM(Hours!$D625:$Z625),) | I625: =IFERROR( Hours!K625/SUM(Hours!$D625:$Z625),) | J625: =IFERROR( Hours!L625/SUM(Hours!$D625:$Z625),) | K625: =IFERROR( Hours!M625/SUM(Hours!$D625:$Z625),) | L625: =IFERROR( Hours!N625/SUM(Hours!$D625:$Z625),) | M625: =IFERROR( Hours!B625/SUM(Hours!$D625:$Z625),) | N625: =IFERROR( Hours!O625/SUM(Hours!$D625:$Z625),) | O625: =IFERROR( Hours!E625/SUM(Hours!$D625:$Z625),) | P625: =IFERROR( Hours!P625/SUM(Hours!$D625:$Z625),) | Q625: =IFERROR( Hours!Q625/SUM(Hours!$D625:$Z625),) | R625: =IFERROR( Hours!R625/SUM(Hours!$D625:$Z625),) | S625: =IFERROR( Hours!S625/SUM(Hours!$D625:$Z625),)
A626: =A625+1 -> 46221 | B626: =IFERROR( Hours!D626/SUM(Hours!$D626:$Z626),) | C626: =IFERROR( Hours!F626/SUM(Hours!$D626:$Z626),) | D626: =IFERROR( Hours!G626/SUM(Hours!$D626:$Z626),) | E626: =IFERROR( Hours!C626/SUM(Hours!$D626:$Z626),) | F626: =IFERROR( Hours!H626/SUM(Hours!$D626:$Z626),) | G626: =IFERROR( Hours!I626/SUM(Hours!$D626:$Z626),) | H626: =IFERROR( Hours!J626/SUM(Hours!$D626:$Z626),) | I626: =IFERROR( Hours!K626/SUM(Hours!$D626:$Z626),) | J626: =IFERROR( Hours!L626/SUM(Hours!$D626:$Z626),) | K626: =IFERROR( Hours!M626/SUM(Hours!$D626:$Z626),) | L626: =IFERROR( Hours!N626/SUM(Hours!$D626:$Z626),) | M626: =IFERROR( Hours!B626/SUM(Hours!$D626:$Z626),) | N626: =IFERROR( Hours!O626/SUM(Hours!$D626:$Z626),) | O626: =IFERROR( Hours!E626/SUM(Hours!$D626:$Z626),) | P626: =IFERROR( Hours!P626/SUM(Hours!$D626:$Z626),) | Q626: =IFERROR( Hours!Q626/SUM(Hours!$D626:$Z626),) | R626: =IFERROR( Hours!R626/SUM(Hours!$D626:$Z626),) | S626: =IFERROR( Hours!S626/SUM(Hours!$D626:$Z626),)
A627: =A626+1 -> 46222 | B627: =IFERROR( Hours!D627/SUM(Hours!$D627:$Z627),) | C627: =IFERROR( Hours!F627/SUM(Hours!$D627:$Z627),) | D627: =IFERROR( Hours!G627/SUM(Hours!$D627:$Z627),) | E627: =IFERROR( Hours!C627/SUM(Hours!$D627:$Z627),) | F627: =IFERROR( Hours!H627/SUM(Hours!$D627:$Z627),) | G627: =IFERROR( Hours!I627/SUM(Hours!$D627:$Z627),) | H627: =IFERROR( Hours!J627/SUM(Hours!$D627:$Z627),) | I627: =IFERROR( Hours!K627/SUM(Hours!$D627:$Z627),) | J627: =IFERROR( Hours!L627/SUM(Hours!$D627:$Z627),) | K627: =IFERROR( Hours!M627/SUM(Hours!$D627:$Z627),) | L627: =IFERROR( Hours!N627/SUM(Hours!$D627:$Z627),) | M627: =IFERROR( Hours!B627/SUM(Hours!$D627:$Z627),) | N627: =IFERROR( Hours!O627/SUM(Hours!$D627:$Z627),) | O627: =IFERROR( Hours!E627/SUM(Hours!$D627:$Z627),) | P627: =IFERROR( Hours!P627/SUM(Hours!$D627:$Z627),) | Q627: =IFERROR( Hours!Q627/SUM(Hours!$D627:$Z627),) | R627: =IFERROR( Hours!R627/SUM(Hours!$D627:$Z627),) | S627: =IFERROR( Hours!S627/SUM(Hours!$D627:$Z627),)
A628: =A627+1 -> 46223 | B628: =IFERROR( Hours!D628/SUM(Hours!$D628:$Z628),) | C628: =IFERROR( Hours!F628/SUM(Hours!$D628:$Z628),) | D628: =IFERROR( Hours!G628/SUM(Hours!$D628:$Z628),) | E628: =IFERROR( Hours!C628/SUM(Hours!$D628:$Z628),) | F628: =IFERROR( Hours!H628/SUM(Hours!$D628:$Z628),) | G628: =IFERROR( Hours!I628/SUM(Hours!$D628:$Z628),) | H628: =IFERROR( Hours!J628/SUM(Hours!$D628:$Z628),) | I628: =IFERROR( Hours!K628/SUM(Hours!$D628:$Z628),) | J628: =IFERROR( Hours!L628/SUM(Hours!$D628:$Z628),) | K628: =IFERROR( Hours!M628/SUM(Hours!$D628:$Z628),) | L628: =IFERROR( Hours!N628/SUM(Hours!$D628:$Z628),) | M628: =IFERROR( Hours!B628/SUM(Hours!$D628:$Z628),) | N628: =IFERROR( Hours!O628/SUM(Hours!$D628:$Z628),) | O628: =IFERROR( Hours!E628/SUM(Hours!$D628:$Z628),) | P628: =IFERROR( Hours!P628/SUM(Hours!$D628:$Z628),) | Q628: =IFERROR( Hours!Q628/SUM(Hours!$D628:$Z628),) | R628: =IFERROR( Hours!R628/SUM(Hours!$D628:$Z628),) | S628: =IFERROR( Hours!S628/SUM(Hours!$D628:$Z628),)
A629: =A628+1 -> 46224 | B629: =IFERROR( Hours!D629/SUM(Hours!$D629:$Z629),) | C629: =IFERROR( Hours!F629/SUM(Hours!$D629:$Z629),) | D629: =IFERROR( Hours!G629/SUM(Hours!$D629:$Z629),) | E629: =IFERROR( Hours!C629/SUM(Hours!$D629:$Z629),) | F629: =IFERROR( Hours!H629/SUM(Hours!$D629:$Z629),) | G629: =IFERROR( Hours!I629/SUM(Hours!$D629:$Z629),) | H629: =IFERROR( Hours!J629/SUM(Hours!$D629:$Z629),) | I629: =IFERROR( Hours!K629/SUM(Hours!$D629:$Z629),) | J629: =IFERROR( Hours!L629/SUM(Hours!$D629:$Z629),) | K629: =IFERROR( Hours!M629/SUM(Hours!$D629:$Z629),) | L629: =IFERROR( Hours!N629/SUM(Hours!$D629:$Z629),) | M629: =IFERROR( Hours!B629/SUM(Hours!$D629:$Z629),) | N629: =IFERROR( Hours!O629/SUM(Hours!$D629:$Z629),) | O629: =IFERROR( Hours!E629/SUM(Hours!$D629:$Z629),) | P629: =IFERROR( Hours!P629/SUM(Hours!$D629:$Z629),) | Q629: =IFERROR( Hours!Q629/SUM(Hours!$D629:$Z629),) | R629: =IFERROR( Hours!R629/SUM(Hours!$D629:$Z629),) | S629: =IFERROR( Hours!S629/SUM(Hours!$D629:$Z629),)
A630: =A629+1 -> 46225 | B630: =IFERROR( Hours!D630/SUM(Hours!$D630:$Z630),) | C630: =IFERROR( Hours!F630/SUM(Hours!$D630:$Z630),) | D630: =IFERROR( Hours!G630/SUM(Hours!$D630:$Z630),) | E630: =IFERROR( Hours!C630/SUM(Hours!$D630:$Z630),) | F630: =IFERROR( Hours!H630/SUM(Hours!$D630:$Z630),) | G630: =IFERROR( Hours!I630/SUM(Hours!$D630:$Z630),) | H630: =IFERROR( Hours!J630/SUM(Hours!$D630:$Z630),) | I630: =IFERROR( Hours!K630/SUM(Hours!$D630:$Z630),) | J630: =IFERROR( Hours!L630/SUM(Hours!$D630:$Z630),) | K630: =IFERROR( Hours!M630/SUM(Hours!$D630:$Z630),) | L630: =IFERROR( Hours!N630/SUM(Hours!$D630:$Z630),) | M630: =IFERROR( Hours!B630/SUM(Hours!$D630:$Z630),) | N630: =IFERROR( Hours!O630/SUM(Hours!$D630:$Z630),) | O630: =IFERROR( Hours!E630/SUM(Hours!$D630:$Z630),) | P630: =IFERROR( Hours!P630/SUM(Hours!$D630:$Z630),) | Q630: =IFERROR( Hours!Q630/SUM(Hours!$D630:$Z630),) | R630: =IFERROR( Hours!R630/SUM(Hours!$D630:$Z630),) | S630: =IFERROR( Hours!S630/SUM(Hours!$D630:$Z630),)
A631: =A630+1 -> 46226 | B631: =IFERROR( Hours!D631/SUM(Hours!$D631:$Z631),) | C631: =IFERROR( Hours!F631/SUM(Hours!$D631:$Z631),) | D631: =IFERROR( Hours!G631/SUM(Hours!$D631:$Z631),) | E631: =IFERROR( Hours!C631/SUM(Hours!$D631:$Z631),) | F631: =IFERROR( Hours!H631/SUM(Hours!$D631:$Z631),) | G631: =IFERROR( Hours!I631/SUM(Hours!$D631:$Z631),) | H631: =IFERROR( Hours!J631/SUM(Hours!$D631:$Z631),) | I631: =IFERROR( Hours!K631/SUM(Hours!$D631:$Z631),) | J631: =IFERROR( Hours!L631/SUM(Hours!$D631:$Z631),) | K631: =IFERROR( Hours!M631/SUM(Hours!$D631:$Z631),) | L631: =IFERROR( Hours!N631/SUM(Hours!$D631:$Z631),) | M631: =IFERROR( Hours!B631/SUM(Hours!$D631:$Z631),) | N631: =IFERROR( Hours!O631/SUM(Hours!$D631:$Z631),) | O631: =IFERROR( Hours!E631/SUM(Hours!$D631:$Z631),) | P631: =IFERROR( Hours!P631/SUM(Hours!$D631:$Z631),) | Q631: =IFERROR( Hours!Q631/SUM(Hours!$D631:$Z631),) | R631: =IFERROR( Hours!R631/SUM(Hours!$D631:$Z631),) | S631: =IFERROR( Hours!S631/SUM(Hours!$D631:$Z631),)
A632: =A631+1 -> 46227 | B632: =IFERROR( Hours!D632/SUM(Hours!$D632:$Z632),) | C632: =IFERROR( Hours!F632/SUM(Hours!$D632:$Z632),) | D632: =IFERROR( Hours!G632/SUM(Hours!$D632:$Z632),) | E632: =IFERROR( Hours!C632/SUM(Hours!$D632:$Z632),) | F632: =IFERROR( Hours!H632/SUM(Hours!$D632:$Z632),) | G632: =IFERROR( Hours!I632/SUM(Hours!$D632:$Z632),) | H632: =IFERROR( Hours!J632/SUM(Hours!$D632:$Z632),) | I632: =IFERROR( Hours!K632/SUM(Hours!$D632:$Z632),) | J632: =IFERROR( Hours!L632/SUM(Hours!$D632:$Z632),) | K632: =IFERROR( Hours!M632/SUM(Hours!$D632:$Z632),) | L632: =IFERROR( Hours!N632/SUM(Hours!$D632:$Z632),) | M632: =IFERROR( Hours!B632/SUM(Hours!$D632:$Z632),) | N632: =IFERROR( Hours!O632/SUM(Hours!$D632:$Z632),) | O632: =IFERROR( Hours!E632/SUM(Hours!$D632:$Z632),) | P632: =IFERROR( Hours!P632/SUM(Hours!$D632:$Z632),) | Q632: =IFERROR( Hours!Q632/SUM(Hours!$D632:$Z632),) | R632: =IFERROR( Hours!R632/SUM(Hours!$D632:$Z632),) | S632: =IFERROR( Hours!S632/SUM(Hours!$D632:$Z632),)
A633: =A632+1 -> 46228 | B633: =IFERROR( Hours!D633/SUM(Hours!$D633:$Z633),) | C633: =IFERROR( Hours!F633/SUM(Hours!$D633:$Z633),) | D633: =IFERROR( Hours!G633/SUM(Hours!$D633:$Z633),) | E633: =IFERROR( Hours!C633/SUM(Hours!$D633:$Z633),) | F633: =IFERROR( Hours!H633/SUM(Hours!$D633:$Z633),) | G633: =IFERROR( Hours!I633/SUM(Hours!$D633:$Z633),) | H633: =IFERROR( Hours!J633/SUM(Hours!$D633:$Z633),) | I633: =IFERROR( Hours!K633/SUM(Hours!$D633:$Z633),) | J633: =IFERROR( Hours!L633/SUM(Hours!$D633:$Z633),) | K633: =IFERROR( Hours!M633/SUM(Hours!$D633:$Z633),) | L633: =IFERROR( Hours!N633/SUM(Hours!$D633:$Z633),) | M633: =IFERROR( Hours!B633/SUM(Hours!$D633:$Z633),) | N633: =IFERROR( Hours!O633/SUM(Hours!$D633:$Z633),) | O633: =IFERROR( Hours!E633/SUM(Hours!$D633:$Z633),) | P633: =IFERROR( Hours!P633/SUM(Hours!$D633:$Z633),) | Q633: =IFERROR( Hours!Q633/SUM(Hours!$D633:$Z633),) | R633: =IFERROR( Hours!R633/SUM(Hours!$D633:$Z633),) | S633: =IFERROR( Hours!S633/SUM(Hours!$D633:$Z633),)
...

Sheet Points
A1: Dates | B1: Αναστασία | C1: Αυτάπ | D1: Εύα | E1: Γιάννης | F1: Χριστιάνα | G1: Κρίστης | H1: Γκάμπριελ | I1: Τάνια | J1: Μαρίνα | K1: Ανέλια | L1: Ναταλία | M1: Παντελίτσα | N1: Μαρία | O1: Διομήδης | P1: Αμάντα | Q1: Ανθούλα | R1: Ραζβάν | S1: Σάντρα | T1: Κρεμένα | U1: Μυρτώ | V1: Λαουρέντζο | W1: Μαρήλια | X1: Μαίρη | Y1: Γκαλίνα | Z1: Μαίρη Ιεαχωβά | AA1: Χριστίνα | AB1: Καλομοίρα | AC1: Χασάν | AD1: Σοφία
A2: 45597 | B2: =Hours_dio!B2*WeightRole!B2 -> 2.4 | C2: =Hours_dio!C2*WeightRole!C2 -> 2.4 | D2: =Hours_dio!D2*WeightRole!D2 -> 2.4 | E2: =Hours_dio!E2*WeightRole!E2 -> 7 | F2: =Hours_dio!F2*WeightRole!F2 -> 6 | G2: =Hours_dio!G2*WeightRole!G2 -> 0 | H2: =Hours_dio!H2*WeightRole!H2 -> 1.2 | I2: =Hours_dio!I2*WeightRole!I2 -> 0 | ... X2: =Hours_dio!X2*WeightRole!X2 -> 0
A3: =A2+1 -> 45598 | B3: =Hours_dio!B3*WeightRole!B3 -> 2.4 | C3: =Hours_dio!C3*WeightRole!C3 -> 2.4 | D3: =Hours_dio!D3*WeightRole!D3 -> 2.4 | E3: =Hours_dio!E3*WeightRole!E3 -> 7 | F3: =Hours_dio!F3*WeightRole!F3 -> 6 | G3: =Hours_dio!G3*WeightRole!G3 -> 4 | H3: =Hours_dio!H3*WeightRole!H3 -> 0 | I3: =Hours_dio!I3*WeightRole!I3 -> 0 | ... X3: =Hours_dio!X3*WeightRole!X3 -> 0
A4: =A3+1 -> 45599 | B4: =Hours_dio!B4*WeightRole!B4 -> 2.4 | C4: =Hours_dio!C4*WeightRole!C4 -> 2.4 | D4: =Hours_dio!D4*WeightRole!D4 -> 2.4 | E4: =Hours_dio!E4*WeightRole!E4 -> 7 | F4: =Hours_dio!F4*WeightRole!F4 -> 6 | G4: =Hours_dio!G4*WeightRole!G4 -> 4 | H4: =Hours_dio!H4*WeightRole!H4 -> 1.2 | I4: =Hours_dio!I4*WeightRole!I4 -> 0 | ... X4: =Hours_dio!X4*WeightRole!X4 -> 0
A5: =A4+1 -> 45600 | B5: =Hours_dio!B5*WeightRole!B5 -> 0 | C5: =Hours_dio!C5*WeightRole!C5 -> 0 | D5: =Hours_dio!D5*WeightRole!D5 -> 0 | E5: =Hours_dio!E5*WeightRole!E5 -> 0 | F5: =Hours_dio!F5*WeightRole!F5 -> 0 | G5: =Hours_dio!G5*WeightRole!G5 -> 0 | H5: =Hours_dio!H5*WeightRole!H5 -> 0 | I5: =Hours_dio!I5*WeightRole!I5 -> 0 | ... X5: =Hours_dio!X5*WeightRole!X5 -> 0
A6: =A5+1 -> 45601 | B6: =Hours_dio!B6*WeightRole!B6 -> 2.4 | C6: =Hours_dio!C6*WeightRole!C6 -> 2.4 | D6: =Hours_dio!D6*WeightRole!D6 -> 2.4 | E6: =Hours_dio!E6*WeightRole!E6 -> 7 | F6: =Hours_dio!F6*WeightRole!F6 -> 6 | G6: =Hours_dio!G6*WeightRole!G6 -> 0 | H6: =Hours_dio!H6*WeightRole!H6 -> 1.2 | I6: =Hours_dio!I6*WeightRole!I6 -> 0 | ... X6: =Hours_dio!X6*WeightRole!X6 -> 0
A7: =A6+1 -> 45602 | B7: =Hours_dio!B7*WeightRole!B7 -> 1.2 | C7: =Hours_dio!C7*WeightRole!C7 -> 2.4 | D7: =Hours_dio!D7*WeightRole!D7 -> 2.4 | E7: =Hours_dio!E7*WeightRole!E7 -> 7 | F7: =Hours_dio!F7*WeightRole!F7 -> 6 | G7: =Hours_dio!G7*WeightRole!G7 -> 4 | H7: =Hours_dio!H7*WeightRole!H7 -> 1.2 | I7: =Hours_dio!I7*WeightRole!I7 -> 1.2 | ... X7: =Hours_dio!X7*WeightRole!X7 -> 0
A8: =A7+1 -> 45603 | B8: =Hours_dio!B8*WeightRole!B8 -> 2.4 | C8: =Hours_dio!C8*WeightRole!C8 -> 0 | D8: =Hours_dio!D8*WeightRole!D8 -> 2.4 | E8: =Hours_dio!E8*WeightRole!E8 -> 7 | F8: =Hours_dio!F8*WeightRole!F8 -> 6 | G8: =Hours_dio!G8*WeightRole!G8 -> 4 | H8: =Hours_dio!H8*WeightRole!H8 -> 1.2 | I8: =Hours_dio!I8*WeightRole!I8 -> 0.6 | ... X8: =Hours_dio!X8*WeightRole!X8 -> 0
A9: =A8+1 -> 45604 | B9: =Hours_dio!B9*WeightRole!B9 -> 2.4 | C9: =Hours_dio!C9*WeightRole!C9 -> 0 | D9: =Hours_dio!D9*WeightRole!D9 -> 2.4 | E9: =Hours_dio!E9*WeightRole!E9 -> 7 | F9: =Hours_dio!F9*WeightRole!F9 -> 6 | G9: =Hours_dio!G9*WeightRole!G9 -> 4 | H9: =Hours_dio!H9*WeightRole!H9 -> 0.6 | I9: =Hours_dio!I9*WeightRole!I9 -> 0.6 | ... X9: =Hours_dio!X9*WeightRole!X9 -> 0
A10: =A9+1 -> 45605 | B10: =Hours_dio!B10*WeightRole!B10 -> 2.4 | C10: =Hours_dio!C10*WeightRole!C10 -> 2.4 | D10: =Hours_dio!D10*WeightRole!D10 -> 2.4 | E10: =Hours_dio!E10*WeightRole!E10 -> 7 | F10: =Hours_dio!F10*WeightRole!F10 -> 6 | G10: =Hours_dio!G10*WeightRole!G10 -> 0 | H10: =Hours_dio!H10*WeightRole!H10 -> 0 | I10: =Hours_dio!I10*WeightRole!I10 -> 0 | ... X10: =Hours_dio!X10*WeightRole!X10 -> 0
A11: =A10+1 -> 45606 | B11: =Hours_dio!B11*WeightRole!B11 -> 2.4 | C11: =Hours_dio!C11*WeightRole!C11 -> 2.4 | D11: =Hours_dio!D11*WeightRole!D11 -> 2.4 | E11: =Hours_dio!E11*WeightRole!E11 -> 7 | F11: =Hours_dio!F11*WeightRole!F11 -> 6 | G11: =Hours_dio!G11*WeightRole!G11 -> 4 | H11: =Hours_dio!H11*WeightRole!H11 -> 1.2 | I11: =Hours_dio!I11*WeightRole!I11 -> 0 | ... X11: =Hours_dio!X11*WeightRole!X11 -> 0
A12: =A11+1 -> 45607 | B12: =Hours_dio!B12*WeightRole!B12 -> 0 | C12: =Hours_dio!C12*WeightRole!C12 -> 0 | D12: =Hours_dio!D12*WeightRole!D12 -> 0 | E12: =Hours_dio!E12*WeightRole!E12 -> 0 | F12: =Hours_dio!F12*WeightRole!F12 -> 0 | G12: =Hours_dio!G12*WeightRole!G12 -> 0 | H12: =Hours_dio!H12*WeightRole!H12 -> 0 | I12: =Hours_dio!I12*WeightRole!I12 -> 0 | ... X12: =Hours_dio!X12*WeightRole!X12 -> 0
A13: =A12+1 -> 45608 | B13: =Hours_dio!B13*WeightRole!B13 -> 3 | C13: =Hours_dio!C13*WeightRole!C13 -> 3 | D13: =Hours_dio!D13*WeightRole!D13 -> 3 | E13: =Hours_dio!E13*WeightRole!E13 -> 7 | F13: =Hours_dio!F13*WeightRole!F13 -> 6 | G13: =Hours_dio!G13*WeightRole!G13 -> 4 | H13: =Hours_dio!H13*WeightRole!H13 -> 0 | I13: =Hours_dio!I13*WeightRole!I13 -> 0 | ... X13: =Hours_dio!X13*WeightRole!X13 -> 0
A14: =A13+1 -> 45609 | B14: =Hours_dio!B14*WeightRole!B14 -> 3 | C14: =Hours_dio!C14*WeightRole!C14 -> 0 | D14: =Hours_dio!D14*WeightRole!D14 -> 3 | E14: =Hours_dio!E14*WeightRole!E14 -> 7 | F14: =Hours_dio!F14*WeightRole!F14 -> 6 | G14: =Hours_dio!G14*WeightRole!G14 -> 0 | H14: =Hours_dio!H14*WeightRole!H14 -> 0 | I14: =Hours_dio!I14*WeightRole!I14 -> 0 | ... X14: =Hours_dio!X14*WeightRole!X14 -> 0
... A275: =A274+1 -> 45870 | B275: =Hours_dio!B275*WeightRole!B275 -> 2.4 | C275: =Hours_dio!C275*WeightRole!C275 -> 2.4 | D275: =Hours_dio!D275*WeightRole!D275 -> 3 | E275: =Hours_dio!E275*WeightRole!E275 -> 7 | F275: =Hours_dio!F275*WeightRole!F275 -> 6 | G275: =Hours_dio!G275*WeightRole!G275 -> 4 | H275: =Hours_dio!H275*WeightRole!H275 -> 0 | I275: =Hours_dio!I275*WeightRole!I275 -> 1.2 | ... X275: =Hours_dio!X275*WeightRole!X275 -> 0
A276: =A275+1 -> 45871 | B276: =Hours_dio!B276*WeightRole!B276 -> 2.4 | C276: =Hours_dio!C276*WeightRole!C276 -> 2.4 | D276: =Hours_dio!D276*WeightRole!D276 -> 3 | E276: =Hours_dio!E276*WeightRole!E276 -> 7 | F276: =Hours_dio!F276*WeightRole!F276 -> 6 | G276: =Hours_dio!G276*WeightRole!G276 -> 4 | H276: =Hours_dio!H276*WeightRole!H276 -> 0 | I276: =Hours_dio!I276*WeightRole!I276 -> 0 | ... Y276: =Hours_dio!Y276*WeightRole!Y276 -> 0
A277: =A276+1 -> 45872 | B277: =Hours_dio!B277*WeightRole!B277 -> 2.4 | C277: =Hours_dio!C277*WeightRole!C277 -> 2.4 | D277: =Hours_dio!D277*WeightRole!D277 -> 3 | E277: =Hours_dio!E277*WeightRole!E277 -> 7 | F277: =Hours_dio!F277*WeightRole!F277 -> 6 | G277: =Hours_dio!G277*WeightRole!G277 -> 4 | H277: =Hours_dio!H277*WeightRole!H277 -> 0 | I277: =Hours_dio!I277*WeightRole!I277 -> 0 | ... Y277: =Hours_dio!Y277*WeightRole!Y277 -> 0
A278: =A277+1 -> 45873 | B278: =Hours_dio!B278*WeightRole!B278 -> 0 | C278: =Hours_dio!C278*WeightRole!C278 -> 0 | D278: =Hours_dio!D278*WeightRole!D278 -> 0 | E278: =Hours_dio!E278*WeightRole!E278 -> 0 | F278: =Hours_dio!F278*WeightRole!F278 -> 0 | G278: =Hours_dio!G278*WeightRole!G278 -> 0 | H278: =Hours_dio!H278*WeightRole!H278 -> 0 | I278: =Hours_dio!I278*WeightRole!I278 -> 0 | ... Y278: =Hours_dio!Y278*WeightRole!Y278 -> 0
